Workbook

Sheet Five Cs
A1: Source: 10-K report (USD in $millions) | M1: Source: 10-K Report (USD in $millions) | Y1: Source: 10-K Report (USD in $millions) | AK1: Source: 10-K Report (USD in $thousands)
A2: Table 1. Amcor Plc Balance Sheet | G2: Table2. Amcor Plc Income Sheet | M2: Table 3. Berry Global Group's Balance sheet | S2: Table 4. Berry Global Group's Income sheet | Y2: Table 5. Sealed Air Corporation's Income Statement | AE2: Table 6. Sealed Air Corporation's Balance Sheet | AK2: Table 7. Sonoco Products Company's Income Statement | AQ2: Table 8. Sonoco Products Company's Balance Sheet
A3: Years | B3: 2021 | C3: 2022 | D3: 2023 | E3: 2024 | G3: Years | H3: 2021 | I3: 2022 | J3: 2023 | K3: 2024 | M3: Years | N3: 2021 | O3: 2022 | P3: 2023 | Q3: 2024 | S3: Years | T3: 2021 | U3: 2022 | V3: 2023 | W3: 2024 | Y3: Years | Z3: 2021 | AA3: 2022 | AB3: 2023 | AC3: 2024 | AE3: Years | AF3: 2021 | AG3: 2022 | AH3: 2023 | AI3: 2024 | AK3: Years | AL3: 2021 | AM3: 2022 | AN3: 2023 | AO3: 2024 | AQ3: Years | AR3: 2021 | AS3: 2022 | AT3: 2023 | AU3: 2024
A4: Current assets: | G4: Net sales | H4: 12861 | I4: 14544 | J4: 14694 | K4: 13640 | M4: Current assets: | S4: Net Sales | T4: 13850 | U4: 14495 | V4: 12664 | W4: 12258 | Y4: Net sales | Z4: 5533.8 | AA4: 5641.9 | AB4: 5488.9 | AC4: 5392.6 | AE4: Current assets: | AK4: Net sales | AL4: 5590438 | AM4: 5859327 | AN4: 5441426 | AO4: 5305365 | AQ4: Current Assets:
A5: Cash and cash equivalents | B5: 850 | C5: 775 | D5: 689 | E5: 588 | G5: Cost of sales | H5: 10129 | I5: 11724 | J5: 11969 | K5: 10928 | M5: Cash and cash equivalents | N5: 1091 | O5: 1410 | P5: 1203 | Q5: 1095 | S5: Costs and expenses: | Y5: Cost of sales | Z5: 3852.9 | AA5: 3869 | AB5: 3847.6 | AC5: 3767.5 | AE5: Cash and cash equivalents | AF5: 561 | AG5: 456.1 | AH5: 346.1 | AI5: 371.8 | AK5: Cost of sales | AL5: 4528528 | AM5: 4634009 | AN5: 4238857 | AO5: 4166132 | AQ5: Cash and cash equivalents | AR5: 170978 | AS5: 227438 | AT5: 138895 | AU5: 431010
A6: Trade receivables, | B6: 1864 | C6: 1935 | D6: 1875 | E6: 1846 | G6: Gross profit | H6: 2732 | I6: 2820 | J6: 2725 | K6: 2712 | M6: Accounts receivable | N6: 1879 | O6: 1777 | P6: 1568 | Q6: 1604 | S6: Cost of goods sold | T6: 11352 | U6: 12123 | V6: 10354 | W6: 10005 | Y6: Gross profit | Z6: 1680.9 | AA6: 1772.9 | AB6: 1641.3 | AC6: 1625.1 | AE6: Trade receivables, | AF6: 620.3 | AG6: 592.4 | AH6: 442.6 | AI6: 443.1 | AK6: Gross profit | AL6: 1061910 | AM6: 1225318 | AN6: 1202569 | AO6: 1139233 | AQ6: Trade accounts receivable | AR6: 755609 | AS6: 862712 | AT6: 686278 | AU6: 907526
A7: Raw materials and supplies | B7: - | C7: - | D7: 992 | E7: 862 | G7: Operating Expenses: | M7: Inventories | N7: 1907 | O7: 1802 | P7: 1557 | Q7: 1631 | S7: Selling, general and administrative | T7: 867 | U7: 850 | V7: 886 | W7: 892 | Y7: Selling, general and administrative expenses | Z7: 772.4 | AA7: 786.2 | AB7: 759.1 | AC7: 752.6 | AE7: Income tax receivables | AF7: 28.8 | AG7: 40.3 | AH7: 44.9 | AI7: 25 | AK7: Selling, general and administrative expenses | AL7: 558180 | AM7: 609578 | AN7: 644540 | AO7: 723833 | AQ7: Other receivables | AR7: 95943 | AS7: 99492 | AT7: 57967 | AU7: 175877
A8: Work in process and finished goods | B8: - | C8: - | D8: 1221 | E8: 1169 | G8: Selling, general, and administrative expenses | H8: -1292 | I8: -1284 | J8: -1246 | K8: -1260 | M8: Prepaid expenses and other current assets | N8: 217 | O8: 175 | P8: 205 | Q8: 244 | S8: Amortization of intangibles | T8: 288 | U8: 257 | V8: 243 | W8: 234 | Y8: (Loss) Gain on disposal and sale of businesses and property and equipment, net | Z8: 45.7 | AA8: 6.3 | AB8: -49.3 | AC8: -16.2 | AE8: Other receivables | AF8: 83.7 | AG8: 104.2 | AH8: 94.2 | AI8: 99.8 | AK8: Restructuring/Asset impairment charges | AL8: 14210 | AM8: 52385 | AN8: 47909 | AO8: 65370 | AQ8: Inventories:
A9: Inventories, net | B9: 1991 | C9: 2439 | D9: =SUM(D7:D8) -> 2213 | E9: =SUM(E7:E8) -> 2031 | G9: Research and development expenses | H9: -100 | I9: -96 | J9: -101 | K9: -106 | M9: Total current assets | N9: 5094 | O9: 5164 | P9: 4533 | Q9: 4574 | S9: Business consolidation and other activities | T9: 51 | U9: 23 | V9: 102 | W9: 190 | Y9: Amortization expense of intangible assets | Z9: 38.8 | AA9: 36.1 | AB9: 62.7 | AC9: 62.6 | AE9: Advances and deposits | AF9: - | AG9: - | AH9: 72.8 | AI9: 36.1 | AK9: (Loss)/Gain on divestiture of business and other assets | AL9: 2667 | AM9: 0 | AN9: 78929 | AO9: -23452 | AQ9: Finished and in process | AR9: 199823 | AS9: 453981 | AT9: 238395 | AU9: 494090
A10: Prepaid expenses and other current assets | B10: 561 | C10: 512 | D10: 531 | E10: 500 | G10: Restructuring, impairment, and other related activities, net | H10: -94 | I10: -234 | J10: 104 | K10: -97 | M10: Property, plant and equipment | N10: 4677 | O10: 4342 | P10: 4576 | Q10: 4575 | S10: Operating income | T10: 1292 | U10: 1242 | V10: 1079 | W10: 937 | Y10: Restructuring charges (Note 13) | Z10: 14.5 | AA10: 12.1 | AB10: 15.6 | AC10: 57.8 | AE10: Inventories, | AF10: 725.7 | AG10: 866.3 | AH10: 774.3 | AI10: 722.2 | AK10: Operating profit | AL10: 486853 | AM10: 563355 | AN10: 589049 | AO10: 326578 | AQ10: Materials and supplies | AR10: 362290 | AS10: 641577 | AT10: 365253 | AU10: 522049
A11: Total current assets | B11: 5266 | C11: 5853 | D11: 5308 | E11: 4965 | G11: Other income/(expenses), net | H11: 75 | I11: 33 | J11: 26 | K11: -35 | M11: Goodwill and intangible assets | N11: 7434 | O11: 6685 | P11: 6684 | Q11: 6624 | S11: Other expense | T11: 51 | U11: 22 | V11: 31 | W11: 15 | Y11: Operating profit | Z11: 900.9 | AA11: 944.8 | AB11: 754.6 | AC11: 735.9 | AE11: Prepaid expenses and other current assets | AF11: 50.1 | AG11: 57.5 | AH11: 188.4 | AI11: 193.8 | AK11: Other (expenses)/income, net | AL11: 0 | AM11: 0 | AN11: 39657 | AO11: -104200 | AQ11: Prepaid expenses | AR11: 74034 | AS11: 76054 | AT11: 103959 | AU11: 197134
A12: Non-current assets: | G12: Operating income | H12: 1321 | I12: 1239 | J12: 1508 | K12: 1214 | M12: Right-of-use assets | N12: 562 | O12: 521 | P12: 625 | Q12: 651 | S12: Interest expense | T12: 336 | U12: 286 | V12: 306 | W12: 311 | Y12: Interest expense, net | Z12: -167.8 | AA12: -162.3 | AB12: -263 | AC12: -247.6 | AE12: Total current assets | AF12: 2069.6 | AG12: 2116.8 | AH12: 1963.3 | AI12: 1891.8 | AK12: Non-operating pension costs | AL12: 568416 | AM12: 7073 | AN12: 14312 | AO12: 13842 | AQ12: Current assets of discontinued operations | AR12: - | AS12: - | AT12: 459618 | AU12: 450874
A13: Property, plant, and equipment, net | B13: 3761 | C13: 3646 | D13: 3762 | E13: 3763 | G13: Interest income | H13: 14 | I13: 24 | J13: 31 | K13: 38 | M13: Other assets | N13: 115 | O13: 244 | P13: 169 | Q13: 189 | S13: Income before income taxes | T13: 905 | U13: 934 | V13: 742 | W13: 611 | Y13: Other expense, net (Note 24) | Z13: -16.9 | AA13: -53.2 | AB13: -61.9 | AC13: -29.9 | AE13: Property and equipment, net (Note 8) | AF13: 1232 | AG13: 1275.9 | AH13: 1416.4 | AI13: 1397.9 | AK13: Interest expense | AL13: 63991 | AM13: 100875 | AN13: 135393 | AO13: 172620 | AQ13: Total Current Assets | AR13: 1658677 | AS13: 2361254 | AT13: 2050365 | AU13: 3178560
A14: Operating Lease, Right-of-Use Asset | B14: 532 | C14: 560 | D14: 533 | E14: 567 | G14: Interest expense | H14: 153 | I14: 159 | J14: 290 | K14: 348 | M14: Total assets | N14: 17882 | O14: 16956 | P14: 16587 | Q14: 16613 | S14: Income tax expense | T14: 172 | U14: 168 | V14: 133 | W14: 95 | Y14: Earnings before income tax provision | Z14: 716.2 | AA14: 729.3 | AB14: 429.7 | AC14: 458.4 | AE14: Goodwill (Note 9) | AF14: 2189.4 | AG14: 2174.5 | AH14: 2892.5 | AI14: 2878.5 | AK14: Interest income | AL14: 4756 | AM14: 4527 | AN14: 10026 | AO14: 27570 | AQ14: Property, Plant and Equipment, Net | AR14: 1297500 | AS14: 1710399 | AT14: 1662767 | AU14: 2718747
A15: Deferred tax assets | B15: 139 | C15: 130 | D15: 134 | E15: 148 | G15: Other non-operating income, net | H15: 11 | I15: 11 | J15: 2 | K15: 3 | M15: Current liabilities: | S15: Net income | T15: 733 | U15: 766 | V15: 609 | W15: 516 | Y15: Income tax provision (Note 20) | Z15: 225 | AA15: 238 | AB15: 90.4 | AC15: 188.9 | AE15: Identifiable intangible assets, net (Note 9) | AF15: 152.6 | AG15: 138.4 | AH15: 439 | AI15: 381.6 | AK15: Income from continuing operations before income taxes | AL15: - | AM15: 459934 | AN15: 489027 | AO15: 63486 | AQ15: Goodwill | AR15: 1324501 | AS15: 1675311 | AT15: 1298011 | AU15: 2525657
A16: Other intangible assets, net | B16: 1835 | C16: 1657 | D16: 1524 | E16: 1391 | G16: Income before income taxes and equity in loss | H16: 1193 | I16: 1115 | J16: 1251 | K16: 907 | M16: Accounts payable | N16: 2041 | O16: 1795 | P16: 1528 | Q16: 1766 | S16: Net income per share ): | Y16: Net earnings from continuing operations | Z16: 491.2 | AA16: 491.3 | AB16: 339.3 | AC16: 269.5 | AE16: Deferred taxes | AF16: 138.4 | AG16: 141.5 | AH16: 130.8 | AI16: 112 | AK16: Provision for income taxes | AL16: -67430 | AM16: 95731 | AN16: 119730 | AO16: 5509 | AQ16: Other Intangible Assets, Net | AR16: 278143 | AS16: 741598 | AT16: 726557 | AU16: 2586698
A17: Goodwill | B17: 5419 | C17: 5285 | D17: 5366 | E17: 5345 | G17: Income tax expense | H17: -261 | I17: -300 | J17: -193 | K17: -163 | M17: Accrued employee costs | N17: 336 | O17: 253 | P17: 273 | Q17: 267 | S17: Basic (in dollars per share) | T17: 5.45 | U17: 5.87 | V17: 5.07 | W17: 4.48 | Y17: (Loss) Gain on sale of discontinued operations, net of tax | Z17: 15.6 | AA17: 0.3 | AB17: 2.3 | AC17: -4.8 | AE17: Non-current assets held for sale | AF17: 1.5 | AG17: 0 | AH17: - | AI17: - | AK17: Income before equity in earnings of affiliates | AL17: -93552 | AM17: 364203 | AN17: 369297 | AO17: 57977 | AQ17: Long-term Deferred Income Taxes | AR17: 25818 | AS17: 29878 | AT17: 30623 | AU17: 17371
A18: Employee benefit assets | B18: 52 | C18: 89 | D18: 67 | E18: 34 | G18: Equity in loss of affiliated companies, net of tax | H18: 19 | I18: 0 | J18: 0 | K18: -4 | M18: Other current liabilities | N18: 788 | O18: 783 | P18: 902 | Q18: 829 | S18: Diluted (in dollars per share) | T18: 5.3 | U18: 5.77 | V18: 4.95 | W18: 4.38 | Y18: Net earnings | Z18: 506.8 | AA18: 491.6 | AB18: 341.6 | AC18: 264.7 | AE18: Operating lease right-of-use-assets (Note 4) | AF18: 63.8 | AG18: 70.2 | AH18: 86.5 | AI18: 98 | AK18: Equity in earnings of affiliates, net of tax | AL18: 10841 | AM18: 14207 | AN18: 10347 | AO18: 9588 | AQ18: Right of Use Asset-Operating Leases | AR18: 268390 | AS18: 296781 | AT18: 233461 | AU18: 307688
A19: Other non-current assets | B19: 184 | C19: 206 | D19: 309 | E19: 311 | G19: Net income | H19: 951 | I19: 815 | J19: 1058 | K19: 740 | M19: Current portion of long-term debt | N19: 21 | O19: 13 | P19: 10 | Q19: 810 | Y19: Basic: | AE19: Other non-current assets | AF19: 382 | AG19: 297.4 | AH19: 272.1 | AI19: 262.3 | AK19: Net income from continuing operations | AL19: 0 | AM19: 378410 | AN19: 379644 | AO19: 67565 | AQ19: Other Assets | AR19: 220206 | AS19: 237719 | AT19: 206064 | AU19: 208759
A20: Total non-current assets | B20: 11922 | C20: 11573 | D20: 11695 | E20: 11559 | G20: Net income attributable to non-controlling interests | H20: -12 | I20: -10 | J20: -10 | K20: -10 | M20: Total current liabilities | N20: 3186 | O20: 2844 | P20: 2713 | Q20: 3672 | Y20: Continuing operations (in dollars per share) | Z20: 3.26 | AA20: 3.37 | AB20: 2.35 | AC20: 1.85 | AE20: Total assets | AF20: 6229.3 | AG20: 6214.7 | AH20: 7200.6 | AI20: 7022.1 | AK20: Net income from discontinued operations | AL20: 0 | AM20: 88570 | AN20: 96257 | AO20: 96375 | AQ20: Non-current assets of discontinued operations | AR20: - | AS20: - | AT20: 984109 | AU20: 964310
A21: Total assets | B21: 17188 | C21: 17426 | D21: 17003 | E21: 16524 | G21: Net income attributable to Amcor plc | H21: 939 | I21: 805 | J21: 1048 | K21: 730 | M21: Long-term debt | N21: 9439 | O21: 9242 | P21: 8970 | Q21: 7505 | Y21: Discontinued operations (in dollars per share) | Z21: 0.1 | AA21: 0 | AB21: 0.02 | AC21: -0.03 | AE21: Current liabilities: | AK21: Net income | AL21: -82711 | AM21: 466980 | AN21: 475901 | AO21: 163940 | AQ21: Total Assets | AR21: 5073235 | AS21: 7052940 | AT21: 7191957 | AU21: 12507790
A22: Current liabilities: | G22: Basic earnings per share: | M22: Deferred income taxes | N22: 568 | O22: 707 | P22: 573 | Q22: 475 | Y22: Net earnings per common share - basic (in dollars per share) | Z22: 3.36 | AA22: 3.37 | AB22: 2.37 | AC22: 1.82 | AE22: Short-term borrowings (Note 15) | AF22: 1.3 | AG22: 6.6 | AH22: 140.7 | AI22: 140.5 | AK22: Net loss/(income) from continuing operations attributable to noncontrolling interests | AL22: 0 | AM22: -284 | AN22: -768 | AO22: 180 | AQ22: Current Liabilities
A23: Current portion of long-term debt | B23: 5 | C23: 14 | D23: 13 | E23: 12 | G23: Basic earnings per share (in USD per share) | H23: $ 0.604 | I23: $ 0.532 | J23: $ 0.709 | K23: $ 0.505 | M23: Employee benefit obligations | N23: 276 | O23: 160 | P23: 193 | Q23: 152 | Y23: Diluted: | AE23: Current portion of long-term debt (Note 15) | AF23: 487.2 | AG23: 434 | AH23: 35.7 | AI23: 64.6 | AK23: Net income from discontinued operations attributable to noncontrolling interests | AL23: 0 | AM23: -259 | AN23: -174 | AO23: -171 | AQ23: Payable to suppliers | AR23: 721312 | AS23: 818885 | AT23: 537877 | AU23: 1130500
A24: Short-term debt | B24: 98 | C24: 136 | D24: 80 | E24: 84 | G24: Diluted earnings per share (in USD per share) | H24: 0.602 | I24: $ 0.529 | J24: $ 0.705 | K24: $ 0.505 | M24: Operating lease liabilities | N24: 466 | O24: 429 | P24: 525 | Q24: 534 | Y24: Continuing operations (in dollars per share) | Z24: 3.22 | AA24: 3.33 | AB24: 2.34 | AC24: 1.84 | AE24: Current portion of operating lease liabilities (Note 4) | AF24: 21.2 | AG24: 24 | AH24: 29.2 | AI24: 29.7 | AK24: Net income attributable to Sonoco | AL24: -85477 | AM24: 466437 | AN24: 474959 | AO24: 163949 | AQ24: Accrued expenses and other | AR24: 290874 | AS24: 295841 | AT24: 265432 | AU24: 463543
A25: Trade payables | B25: 2574 | C25: 3073 | D25: 2690 | E25: 2580 | M25: Other long-term liabilities | N25: 767 | O25: 378 | P25: 397 | Q25: 667 | Y25: Discontinued operations (in dollars per share) | Z25: 0.1 | AA25: 0 | AB25: 0.02 | AC25: -0.03 | AE25: Accounts payable | AF25: 959.9 | AG25: 865.6 | AH25: 764.6 | AI25: 771 | AK25: Weighted average common shares outstanding: | AQ25: Accrued wages and other compensation | AR25: 90476 | AS25: 109830 | AT25: 63767 | AU25: 140912
A26: Accrued employee costs | B26: 523 | C26: 471 | D26: 396 | E26: 399 | M26: Total liabilities | N26: 14702 | O26: 13760 | P26: 13371 | Q26: 13005 | Y26: Net earnings per common share - diluted (in dollars per share) | Z26: 3.32 | AA26: 3.33 | AB26: 2.36 | AC26: 1.81 | AE26: Accrued restructuring costs (Note 13) | AF26: 10.2 | AG26: 14.7 | AH26: 23.1 | AI26: 42.6 | AK26: Basic (in shares) | AL26: 99608 | AM26: 97991 | AN26: 98294 | AO26: 98637 | AQ26: Notes payable and current portion of long-term debt | AR26: 411557 | AS26: 502440 | AT26: 38934 | AU26: 2054525
A27: Other current liabilities | B27: 1145 | C27: 1344 | D27: 1297 | E27: 1186 | M27: Stockholders' equity: | Y27: Weighted average number of common shares outstanding in millions: (Note 25) | AE27: Income tax payable | AF27: 22.7 | AG27: 19.9 | AH27: 28.7 | AI27: 53.3 | AK27: Assuming exercise of awards (in shares) | AL27: 0 | AM27: 741 | AN27: 596 | AO27: 653 | AQ27: Accrued taxes | AR27: 11544 | AS27: 16905 | AT27: 10863 | AU27: 6755
A28: Total current liabilities | B28: 4345 | C28: 5103 | D28: 4476 | E28: 4261 | M28: Common stock (115.0 and 115.5 shares issued, respectively) | N28: 1 | O28: 1 | P28: 1 | Q28: 1 | Y28: Basic (in shares) | Z28: 150.9 | AA28: 145.9 | AB28: 144.4 | AC28: 145.5 | AE28: Other current liabilities (Note 14) | AF28: 504.8 | AG28: 717 | AH28: 487 | AI28: 533.8 | AK28: Diluted (in shares) | AL28: 99608 | AM28: 98732 | AN28: 98890 | AO28: 99290 | AQ28: Current liabilities of discontinued operations | AR28: - | AS28: - | AT28: 248404 | AU28: 242056
A29: Non-current liabilities: | M29: Additional paid-in capital | N29: 1134 | O29: 1177 | P29: 1231 | Q29: 1321 | Y29: Diluted (in shares) | Z29: 152.4 | AA29: 147.4 | AB29: 144.9 | AC29: 146 | AE29: Total current liabilities | AF29: 2007.3 | AG29: 2081.8 | AH29: 1509 | AI29: 1635.5 | AK29: Basic earnings per common share: | AQ29: Total Current Liabilities | AR29: 1525763 | AS29: 1743901 | AT29: 1165277 | AU29: 4038291
A30: Long-term debt, less current portion | B30: 6186 | C30: 6340 | D30: 6653 | E30: 6603 | M30: Retained earnings | N30: 2341 | O30: 2421 | P30: 2320 | Q30: 2581 | AE30: Long-term debt, less current portion (Note 15) | AF30: 3219.6 | AG30: 3237.9 | AH30: 4513.9 | AI30: 4198.8 | AK30: Continuing operations (usd per share) | AL30: - | AM30: 3.86 | AN30: 3.85 | AO30: 0.69 | AQ30: Long-term Debt | AR30: 1199106 | AS30: 2719783 | AT30: 2998002 | AU30: 4985496
A31: Operating lease liabilities | B31: 462 | C31: 493 | D31: 463 | E31: 488 | M31: Accumulated other comprehensive loss | N31: -296 | O31: -403 | P31: -336 | Q31: -295 | AE31: Long-term operating lease liabilities, less current portion (Note 4) | AF31: 44.5 | AG31: 49.6 | AH31: 66.7 | AI31: 74.8 | AK31: Discontinued operations (usd per share) | AL31: - | AM31: 0.9 | AN31: 0.98 | AO31: 0.97 | AQ31: Noncurrent Operating Lease Liabilities | AR31: 234167 | AS31: 250994 | AT31: 192703 | AU31: 258735
A32: Deferred tax liabilities | B32: 696 | C32: 677 | D32: 616 | E32: 584 | M32: Total stockholders' equity | N32: 3180 | O32: 3196 | P32: 3216 | Q32: 3608 | AE32: Deferred taxes | AF32: 46.7 | AG32: 33.4 | AH32: 35.8 | AI32: 26.1 | AK32: Basic earnings per share attributable to Sonoco (usd per share) | AL32: - | AM32: 4.76 | AN32: 4.83 | AO32: 1.66 | AQ32: Pension and Other Postretirement Benefits | AR32: 158265 | AS32: 120084 | AT32: 142784 | AU32: 180827
A33: Employee benefit obligations | B33: 307 | C33: 201 | D33: 224 | E33: 217 | M33: Total liabilities and stockholders' equity | N33: 17882 | O33: 16956 | P33: 16587 | Q33: 16613 | AE33: Non-current liabilities held for sale | AF33: 0.9 | AG33: 0 | AH33: 0 | AI33: 0 | AK33: Diluted earnings per common share: | AL33: - | AQ33: Deferred Income Taxes | AR33: 70482 | AS33: 107293 | AT33: 93854 | AU33: 583470
A34: Other non-current liabilities | B34: 371 | C34: 471 | D34: 481 | E34: 418 | AE34: Other non-current liabilities (Note 14) | AF34: 661.6 | AG34: 467.9 | AH34: 525.7 | AI34: 462.4 | AK34: Continuing operations (usd per share) | AL34: - | AM34: 3.83 | AN34: 3.83 | AO34: 0.68 | AQ34: Other Liabilities | AR34: 35911 | AS34: 38088 | AT34: 49362 | AU34: 60847
A35: Total non-current liabilities | B35: 8022 | C35: 8182 | D35: 8437 | E35: 8310 | AE35: Total liabilities | AF35: 5980.6 | AG35: 5870.6 | AH35: 6651.1 | AI35: 6397.6 | AK35: Diluted - attributable to Sonoco discontinued operations (usd per share) | AL35: - | AM35: 0.89 | AN35: 0.97 | AO35: 0.97 | AQ35: Non-current liabilities of discontinued operations | AR35: - | AS35: - | AT35: 118140 | AU35: 113911
A36: Total liabilities | B36: 12367 | C36: 13285 | D36: 12913 | E36: 12571 | AE36: Commitments and contingencies (Note 21) | AK36: Diluted earnings per share attributable to Sonoco (usd per share) | AL36: - | AM36: 4.72 | AN36: 4.8 | AO36: 1.65 | AQ36: Total Liabilities | AR36: 3223694 | AS36: 4980143 | AT36: 4760122 | AU36: 10221577
A37: Commitments and contingencies (See Note $19) | AE37: Stockholders’ equity: | AQ37: Commitments and Contingencies (Note 18)
A38: Amcor plc shareholders’ equity: | AE38: Preferred stock, | AF38: 0 | AG38: 0 | AH38: 0 | AI38: 0 | AQ38: Sonoco Shareholders’ Equity
A39: Issued (1,445 and 1,448 million shares, respectively) | B39: 15 | C39: 15 | D39: 14 | E39: 14 | AE39: Common stock | AF39: 23.2 | AG39: 23.3 | AH39: 15.4 | AI39: 15.5 | AQ39: Serial preferred stock
A40: Additional paid-in capital | B40: 5092 | C40: 4431 | D40: 4021 | E40: 4019 | AE40: Additional paid-in capital | AF40: 2123.4 | AG40: 2155.3 | AH40: 1429.5 | AI40: 1445.7 | AQ40: Common shares | AR40: 7175 | AS40: 7175 | AT40: 7175 | AU40: 7175
...

Sheet Risk Premium
B2: Table 1. Firm's Bond Rating | G2: Table 2A. Bond's Rating and Annual Returns
B3: Firm name | C3: Amcor Plc | D3: Rating (S&P) | E3: BBB | H3: 1-year | I3: 2-year | J3: 3-year | K3: 4-year | L3: 5-year
G4: AAA | H4: 0.025 | I4: 0.032 | J4: 0.037 | K4: 0.0445 | L4: 0.055
G5: AA | H5: 0.027 | I5: 0.036 | J5: 0.043 | K5: 0.0515 | L5: 0.0612
B6: Table 3. Firm's Expected Repayment Probability | G6: A | H6: 0.031 | I6: 0.039 | J6: 0.046 | K6: 0.0535 | L6: 0.063
C7: 1-year | D7: 2-year | E7: 3-year | G7: BBB | H7: 0.043 | I7: 0.046 | J7: 0.0522 | K7: 0.063 | L7: 0.074
B8: BBB | C8: =(1+H15)/(1+H7) -> 0.97315436 | D8: =(1+I15)/(1+I7) -> 0.97609943 | E8: =(1+J15)/(1+J7) -> 0.9741494 | G8: BB | H8: 0.048 | I8: 0.055 | J8: 0.0655 | K8: 0.0735 | L8: 0.0845
G9: B | H9: 0.057 | I9: 0.065 | J9: 0.078 | K9: 0.0895 | L9: 0.102
G10: CCC | H10: 0.065 | I10: 0.071 | J10: 0.082 | K10: 0.1055 | L10: 0.111
B11: Table A. Firm's Expected Default Probability | G11: CC | H11: 0.078 | I11: 0.088 | J11: 0.096 | K11: 0.105 | L11: 0.128
C12: 1-year | D12: 2-year | E12: 3-year
B13: Amcor (BBB) | C13: =1-C8 -> 0.026845638 | D13: =1-D8 -> 0.023900574 | E13: =1-E8 -> 0.025850599 | G13: Table 2B. Government bond yields with different maturities
G14: Maturity | H14: 1-year | I14: 2-year | J14: 3-year | K14: 4-year | L14: 5-year
B15: Cumulative Default Probability | E15: =1-PRODUCT(C8:E8) -> 0.07465995 | G15: Returns | H15: 0.015 | I15: 0.021 | J15: 0.025 | K15: 0.032 | L15: 0.041

Sheet Altman Score
B1: Table 1. Amcor Plc Balance Sheet
B2: Years | C2: 2021 | D2: 2022 | E2: 2023 | F2: 2024
B3: Current assets:
B4: Cash and cash equivalents | C4: 850 | D4: 775 | E4: 689 | F4: 588
B5: Trade receivables, | C5: 1864 | D5: 1935 | E5: 1875 | F5: 1846
B6: Raw materials and supplies | C6: - | D6: - | E6: 992 | F6: 862
B7: Work in process and finished goods | C7: - | D7: - | E7: 1221 | F7: 1169
B8: Inventories, net | C8: 1991 | D8: 2439 | E8: =SUM(E6:E7) -> 2213 | F8: =SUM(F6:F7) -> 2031
B9: Prepaid expenses and other current assets | C9: 561 | D9: 512 | E9: 531 | F9: 500
B10: Total current assets | C10: 5266 | D10: 5853 | E10: 5308 | F10: 4965
B11: Non-current assets:
B12: Property, plant, and equipment, net | C12: 3761 | D12: 3646 | E12: 3762 | F12: 3763
B13: Operating Lease, Right-of-Use Asset | C13: 532 | D13: 560 | E13: 533 | F13: 567
B14: Deferred tax assets | C14: 139 | D14: 130 | E14: 134 | F14: 148
B15: Other intangible assets, net | C15: 1835 | D15: 1657 | E15: 1524 | F15: 1391
B16: Goodwill | C16: 5419 | D16: 5285 | E16: 5366 | F16: 5345
B17: Employee benefit assets | C17: 52 | D17: 89 | E17: 67 | F17: 34
B18: Other non-current assets | C18: 184 | D18: 206 | E18: 309 | F18: 311
B19: Total non-current assets | C19: 11922 | D19: 11573 | E19: 11695 | F19: 11559
B20: Total assets | C20: 17188 | D20: 17426 | E20: 17003 | F20: 16524
B21: Current liabilities:
B22: Current portion of long-term debt | C22: 5 | D22: 14 | E22: 13 | F22: 12
B23: Short-term debt | C23: 98 | D23: 136 | E23: 80 | F23: 84
B24: Trade payables | C24: 2574 | D24: 3073 | E24: 2690 | F24: 2580
B25: Accrued employee costs | C25: 523 | D25: 471 | E25: 396 | F25: 399
B26: Other current liabilities | C26: 1145 | D26: 1344 | E26: 1297 | F26: 1186
B27: Total current liabilities | C27: 4345 | D27: 5103 | E27: 4476 | F27: 4261
B28: Non-current liabilities:
B29: Long-term debt, less current portion | C29: 6186 | D29: 6340 | E29: 6653 | F29: 6603 | I29: (FY 2024)
B30: Operating lease liabilities | C30: 462 | D30: 493 | E30: 463 | F30: 488 | I30: Variables | J30: Value $million | L30: X1 = Working Capital / Total Assets
B31: Deferred tax liabilities | C31: 696 | D31: 677 | E31: 616 | F31: 584 | I31: Working Capital (CA-CL) | J31: =F10-F27 -> 704 | L31: X2 = Retained Earnings / Total Assets
B32: Employee benefit obligations | C32: 307 | D32: 201 | E32: 224 | F32: 217 | I32: Retained Earnings | J32: =F40 -> 879 | L32: X3 = EBIT / Total Assets
B33: Other non-current liabilities | C33: 371 | D33: 471 | E33: 481 | F33: 418 | I33: Earnings before interest and Taxes | J33: ='Five Cs'!K12 -> 1214 | L33: X4 = Market Value of Equity / Total Liabilities
B34: Total non-current liabilities | C34: 8022 | D34: 8182 | E34: 8437 | F34: 8310 | I34: Market Value of Equity | J34: =J38*J39 -> 13621.92 | L34: X5 = Sales / Total Assets
B35: Total liabilities | C35: 12367 | D35: 13285 | E35: 12913 | F35: 12571 | I35: Sales | J35: ='Five Cs'!K4 -> 13640
B36: Commitments and contingencies (See Note $19) | I36: Total Asset | J36: =F20 -> 16524 | L36: Z-Score Range | M36: Zone
B37: Amcor plc shareholders’ equity: | I37: Book Value of Total Liabilities | J37: =F35 -> 12571 | L37: Z > 2.99 | M37: Safe Zone -> Low risk of bankruptcy; strong financial health
B38: Issued (1,445 and 1,448 million shares, respectively) | C38: 15 | D38: 15 | E38: 14 | F38: 14 | I38: Share Price | J38: ='KMV model'!L3 -> 9.44 | L38: 1.81 < Z < 2.99 | M38: Grey Zone -> Moderate risk; uncertain financial condition
B39: Additional paid-in capital | C39: 5092 | D39: 4431 | E39: 4021 | F39: 4019 | I39: Shares Outstanding | J39: 1443 | L39: Z < 1.81 | M39: Distress Zone -> High risk of financial distress or bankruptcy
B40: Retained earnings | C40: 452 | D40: 534 | E40: 865 | F40: 879
...

Sheet KMV model
J1: Source: NASDAQ | K1: Daily Historical Prices (2024-2025)
B2: Table 1 | K2: Date | L2: Adj Close | M2: Daily Return
B3: Firm's Information Needed for KMV calculations | C3: (in USD $millions) | F3: Table 2. Expected Default Frequency table | K3: 05/16/2025 | L3: 9.44 | M3: =(L3/L4)-1 -> 0.01396348
B4: Market value of Equity (E) | C4: ='Altman Score'!J34 -> 13621.92 | F4: DD | G4: EDF | K4: 05/15/2025 | L4: 9.31 | M4: =(L4/L5)-1 -> 0.01416122
B5: Book Value of Liabilities (D) | C5: ='Altman Score'!J37 -> 12571 | F5: 1 | G5: 0.5 | K5: 05/14/2025 | L5: 9.18 | M5: =(L5/L6)-1 -> 0.0010905125 | P5: Daily Volatility | Q5: =_xlfn.STDEV.S(M3:M254) -> 0.014506216
B6: Market Value of Assets (V) | C6: =C4+C5 -> 26192.92 | F6: 2 | G6: 0.35 | K6: 05/13/2025 | L6: 9.17 | M6: =(L6/L7)-1 -> -0.018201285 | P6: Annualised Volatility | Q6: =Q5*SQRT(252) -> 0.23027904
B7: Volatility of Equity (σe) | C7: =Q6 -> 0.23027904 | F7: 3 | G7: 0.1 | K7: 45996 | L7: 9.34 | M7: =(L7/L8)-1 -> 0.024122807
B8: Volatility of Assets (σa) | C8: =C7*(C4/C6) -> 0.11975918 | F8: 4 | G8: 0.05 | K8: 45905 | L8: 9.12 | M8: =(L8/L9)-1 -> -0.0054525627
B9: Current Liability | C9: ='Altman Score'!F27 -> 4261 | F9: 5 | G9: 0.02 | K9: 45874 | L9: 9.17 | M9: =(L9/L10)-1 -> 0.006586169
B10: Long-term Liability | C10: ='Altman Score'!F29 -> 6603 | F10: 6 | G10: 0.01 | K10: 45843 | L10: 9.11 | M10: =(L10/L11)-1 -> -0.0076252723
B11: Payout Ratio | C11: 0.9808 | F11: 7 | G11: 0.001 | K11: 45813 | L11: 9.18 | M11: =(L11/L12)-1 -> -0.01396348
B12: Retention Ratio | C12: =1-C11 -> 0.0192 | F12: 8 | G12: 0.0005 | K12: 45782 | L12: 9.31 | M12: =(L12/L13)-1 -> -0.0010729614
B13: Return on Equity (ROE) | C13: ='Five Cs'!K19/'Five Cs'!E46 -> 0.1871996 | F13: 9 | G13: 0.0001 | K13: 45693 | L13: 9.32 | M13: =(L13/L14)-1 -> 0.026431718
B14: Growth Rate (g) | C14: =C12*C13 -> 0.0035942322 | F14: 10 | G14: 5e-05 | K14: 45662 | L14: 9.08 | M14: =(L14/L15)-1 -> -0.013043478
K15: 04/30/2025 | L15: 9.2 | M15: =(L15/L16)-1 -> -0.013933548
K16: 04/29/2025 | L16: 9.33 | M16: =(L16/L17)-1 -> -0.031152648
K17: 04/28/2025 | L17: 9.63 | M17: =(L17/L18)-1 -> 0.0094339623
K18: 04/25/2025 | L18: 9.54 | M18: =(L18/L19)-1 -> -0.01242236
K19: 04/24/2025 | L19: 9.66 | M19: =(L19/L20)-1 -> 0.014705882
K20: 04/23/2025 | L20: 9.52 | M20: =(L20/L21)-1 -> -0.0041841004
B21: Table A. Amcor Plc's EDF | K21: 04/22/2025 | L21: 9.56 | M21: =(L21/L22)-1 -> 0.026852846
C22: 1-year | D22: 2-year | E22: 3-year | K22: 04/21/2025 | L22: 9.31 | M22: =(L22/L23)-1 -> -0.0085197018
B23: 1. Expected Market Value of Assets | C23: =$C$6*((1+$C$14)^1) -> 26287.063 | D23: =$C$6*((1+$C$14)^2) -> 26381.545 | E23: =$C$6*((1+$C$14)^3) -> 26476.367 | K23: 04/17/2025 | L23: 9.39 | M23: =(L23/L24)-1 -> 0.015135135
B24: 2. Standard deviations of Assets | C24: =$C$8 -> 0.11975918 | D24: =$C$8 -> 0.11975918 | E24: =$C$8 -> 0.11975918 | K24: 04/16/2025 | L24: 9.25 | M24: =(L24/L25)-1 -> -0.011752137
B25: 3. Default Point | C25: =($C$9+(0.5*$C$10))*((1+$C$14)^1) -> 7589.6814 | D25: =($C$9+(0.5*$C$10))*((1+$C$14)^2) -> 7616.9605 | E25: =($C$9+(0.5*$C$10))*((1+$C$14)^3) -> 7644.3376 | K25: 04/15/2025 | L25: 9.36 | M25: =(L25/L26)-1 -> -0.018867925
B26: 4. DD | C26: =(C23-C25)/(C23*C24) -> 5.9392268 | D26: =(D23-D25)/(D23*D24) -> 5.9392268 | E26: =(E23-E25)/(E23*E24) -> 5.9392268 | K26: 04/14/2025 | L26: 9.54 | M26: =(L26/L27)-1 -> 0.022508039
B27: 5. EDF | C27: =$G$10 -> 0.01 | D27: =$G$10 -> 0.01 | E27: =$G$10 -> 0.01 | K27: 45965 | L27: 9.33 | M27: =(L27/L28)-1 -> 0.034368071
K28: 45934 | L28: 9.02 | M28: =(L28/L29)-1 -> 0
K29: 45904 | L29: 9.02 | M29: =(L29/L30)-1 -> 0.052508751
K30: 45873 | L30: 8.57 | M30: =(L30/L31)-1 -> -0.039237668
K31: 45842 | L31: 8.92 | M31: =(L31/L32)-1 -> -0.032537961
K32: 45751 | L32: 9.22 | M32: =(L32/L33)-1 -> -0.036572623
K33: 45720 | L33: 9.57 | M33: =(L33/L34)-1 -> -0.023469388
K34: 45692 | L34: 9.8 | M34: =(L34/L35)-1 -> -0.001019368
K35: 45661 | L35: 9.81 | M35: =(L35/L36)-1 -> 0.011340206
K36: 03/31/2025 | L36: 9.7 | M36: =(L36/L37)-1 -> 0.0062240664
K37: 03/28/2025 | L37: 9.64 | M37: =(L37/L38)-1 -> -0.0072090628
K38: 03/27/2025 | L38: 9.71 | M38: =(L38/L39)-1 -> 0.011458333
K39: 03/26/2025 | L39: 9.6 | M39: =(L39/L40)-1 -> 0.016949153
K40: 03/25/2025 | L40: 9.44 | M40: =(L40/L41)-1 -> -0.011518325
...

Sheet Amcor USD Fin stmnt
B4: Consolidated Statements of Income - USD ($) | C4: 12 Months Ended
B5: $ in Millions
C6: Jun. 30, 2024 | D6: Jun. 30, 2023 | E6: Jun. 30, 2022 | F6: Jun. 30, 2021
B8: Net sales | C8: 13640 | D8: 14694 | E8: 14544 | F8: 12861
B9: Cost of sales | C9: -10928 | D9: -11969 | E9: -11724 | F9: -10129
B10: Gross profit | C10: 2712 | D10: 2725 | E10: 2820 | F10: 2732
B11: Operating Expenses:
B12: Selling, general, and administrative expenses | C12: -1260 | D12: -1246 | E12: -1284 | F12: -1292
B13: Research and development expenses | C13: -106 | D13: -101 | E13: -96 | F13: -100
B14: Restructuring, impairment, and other related activities, net | C14: -97 | D14: 104 | E14: -234 | F14: -94
B15: Other income/(expenses), net | C15: -35 | D15: 26 | E15: 33 | F15: 75
B16: Operating income | C16: 1214 | D16: 1508 | E16: 1239 | F16: 1321
B17: Interest income | C17: 38 | D17: 31 | E17: 24 | F17: 14
B18: Interest expense | C18: -348 | D18: -290 | E18: -159 | F18: -153
B19: Other non-operating income, net | C19: 3 | D19: 2 | E19: 11 | F19: 11
B20: Income before income taxes and equity in loss of affiliated companies | C20: 907 | D20: 1251 | E20: 1115 | F20: 1193
B21: Income tax expense | C21: -163 | D21: -193 | E21: -300 | F21: -261
B22: Equity in loss of affiliated companies, net of tax | C22: -4 | D22: 0 | E22: 0 | F22: 19
B23: Net income | C23: 740 | D23: 1058 | E23: 815 | F23: 951
... B25: Net income attributable to Amcor plc | C25: 730 | D25: 1048 | E25: 805 | F25: 939
B26: Basic earnings per share:
B27: Basic earnings per share (in USD per share) | C27: $ 0.505 | D27: $ 0.709 | E27: $ 0.532 | F27: $ 0.604
B28: Diluted earnings per share (in USD per share) | C28: $ 0.505 | D28: $ 0.705 | E28: $ 0.529 | F28: 0.602
B30: Consolidated Balance Sheets - USD ($) | C30: Jun. 30, 2024 | D30: Jun. 30, 2023 | E30: Jun. 30, 2022 | F30: Jun. 30, 2021
B31: $ in Millions
B32: Current assets:
B33: Cash and cash equivalents | C33: 588 | D33: 689 | E33: 775 | F33: 850
B34: Trade receivables, | C34: 1846 | D34: 1875 | E34: 1935 | F34: 1864
B35: Raw materials and supplies | C35: 862 | D35: 992 | E35: - | F35: -
B36: Work in process and finished goods | C36: 1169 | D36: 1221 | E36: - | F36: -
B37: Inventories, net | C37: =SUM(C35:C36) -> 2031 | D37: =SUM(D35:D36) -> 2213 | E37: 2439 | F37: 1991
B38: Prepaid expenses and other current assets | C38: 500 | D38: 531 | E38: 512 | F38: 561
B39: Total current assets | C39: 4965 | D39: 5308 | E39: 5853 | F39: 5266
B40: Non-current assets:
B41: Property, plant, and equipment, net | C41: 3763 | D41: 3762 | E41: 3646 | F41: 3761
B42: Operating Lease, Right-of-Use Asset | C42: 567 | D42: 533 | E42: 560 | F42: 532
B43: Deferred tax assets | C43: 148 | D43: 134 | E43: 130 | F43: 139
B44: Other intangible assets, net | C44: 1391 | D44: 1524 | E44: 1657 | F44: 1835
B45: Goodwill | C45: 5345 | D45: 5366 | E45: 5285 | F45: 5419
B46: Employee benefit assets | C46: 34 | D46: 67 | E46: 89 | F46: 52
...
