Workbook

Sheet WACC
A1: Target Company.: Bega Cheese | E1: Acquiring Company.: Woolsworths
A2: WACC CALCULATION | E2: WACC CALCULATION
A3: ((Ke*Equity/Equity+Debt)+(Debt*Kd*(1-T))) | E3: ((Ke*Equity/Equity+Debt)+(Debt*Kd*(1-T)/100))
A4: Risk free rate (Rf) * | B4: 0.0442 | C4: as of 3rd May 2024 | E4: Risk free rate (Rf) * | F4: =B4 -> 0.0442
A5: Cost of debt (Kd ) | B5: =B33 -> 0.051594948 | E5: Cost of debt (Kd ) | F5: =F30 -> 0.047612551
A6: Market rate (Rm) [Rm = Rf + ERP] | B6: =B7+B4 -> 0.0902 | E6: Market rate (Rm) [Rm = Rf + ERP] | F6: =B6 -> 0.0902
A7: Equity Risk Premium (Rm - Rf) * | B7: 0.046 | E7: Equity Risk Premium (Rm - Rf) * | F7: =B7 -> 0.046
A8: Equity (100-debt) | B8: =1-B9 -> 0.68241773 | E8: Equity (100-debt) | F8: =F32 -> 0.30930506
A9: Debt | B9: =B34 -> 0.31758227 | E9: Debt | F9: =F31 -> 0.69069494
A10: Beta (β) | B10: =B23 -> 0.49975 | E10: Beta (β) | F10: =F23 -> 0.4275
A11: Tax rate (T) | B11: 0.3 | C11: as mentioned in Annual Report | E11: Tax rate (T) | F11: 0.3
A12: Ke (CAPM) = (Rf+β(Rm-Rf)) | B12: =B4+((B10)*(B6-B4)) -> 0.0671885 | E12: Ke (CAPM) = (Rf+β(Rm-Rf)) | F12: =F4+(F10*F7) -> 0.063865
A13: WACC | B13: =(B8*B12)+((B9*B5)*(1-B11)) -> 0.057320572 | E13: WACC | F13: =(F12*F8)+((F9*F5)*(1-F11)) -> 0.042773792
A17: Beta (5Y) | E17: Beta (5Y)
A18: Sources of Reference | B18: Values | E18: Sources of Reference | F18: Values
A19: https://finbox.com/ASX:BGA/models/wacc/ | B19: 0.519 | E19: https://finbox.com/ASX:WOW/explorer/beta/ | F19: 0.27
A20: https://au.finance.yahoo.com/quote/BGA.AX/key-statistics/ | B20: 0.52 | E20: https://au.finance.yahoo.com/quote/WOW.AX/key-statistics/ | F20: 0.27
A21: https://www.tradingview.com/symbols/ASX-BGA/ | B21: 0.53 | E21: WOW.AX - | Stock Price & Latest News | Reuters | F21: 0.55
A22: https://markets.ft.com/data/equities/tearsheet/summary?s=BGA:ASX | B22: 0.43 | E22: https://datanalysis-morningstar-com-au.ap1.proxy.openathens.net/af/company/fullcompanyreport?ASXCode=WOW&licensee=datpremium&xsl-printfriendly=yes&xsl-printfullreport=yes | F22: 0.62
A23: Average | B23: =AVERAGE(B19:B22) -> 0.49975 | E23: Average | F23: =AVERAGE(F19:F22) -> 0.4275
A26: Capital Structure:Working Note | E26: Capital Structure : Working Note | G26: annual report 2023
A27: Interest Expense | B27: ='Income Statement '!F18 *-1 -> 24100000 | E27: Interest Expense | F27: =698000000 -> 698000000
A28: Short term debt | B28: ='Balance Sheet '!F22 -> 17200000 | E28: Total Debt | F28: 14660000000
A29: Long term debt | B29: ='Balance Sheet '!F28 -> 449900000 | E29: Total Equity | F29: 6565000000
A30: Total Debt | B30: =SUM(B28:B29) -> 467100000 | E30: Cost of Debt (Kd) | F30: =F27/F28 -> 0.047612551
A31: Total Equity | B31: ='Balance Sheet '!F40 -> 1003700000 | E31: Debt to value ratio (D/V) | F31: =F28/(F28+F29) -> 0.69069494
E32: Equity to value ratio (E/V) | F32: =1-F31 -> 0.30930506
A33: Cost of Debt (Kd) | B33: =B27/B30 -> 0.051594948
A34: Debt to value ratio (D/V) | B34: =B30/(B30+B31) -> 0.31758227
A35: Equity to value ratio (E/V) | B35: =1-B34 -> 0.68241773
A38: Assumptions made* :
A39: 1. Risk free rate: 10Y govt bond yield | B39: Source (https://www.bloomberg.com/markets/rates-bonds/government-bonds/australia)
A40: 2. Equity Risk Premium (Rm-Rf) | B40: Source(https://pages.stern.nyu.edu/~adamodar/New_Home_Page/datafile/ctryprem.html)

Sheet Fundamental Valuation
C1: Bega Cheese's Financial Summary and Projections, 2019-2028
B2: 2018 | C2: 2019 | D2: 2020 | E2: 2021 | F2: 2022 | G2: 2023 | H2: 2024E | I2: 2025E | J2: 2026E | K2: 2027E | L2: 2028E
A3: Operating Revenue | B3: 1445018000 | C3: ='Income Statement '!B3 -> 1427167000 | D3: ='Income Statement '!C3 -> 1501079000 | E3: ='Income Statement '!D3 -> 2081600000 | F3: ='Income Statement '!E3 -> 3018300000 | G3: ='Income Statement '!F3 -> 3387200000 | H3: =G3*(1+(G7+$B$11)) -> 3960385770 | I3: =H3*(1+(H7+$B$11)) -> 4816704809 | J3: =I3*(1+(I7+$B$11)) -> 6084563233 | K3: =J3*(1+(J7+$B$11)) -> 7972123241 | L3: =K3*(1+(K7+$B$11)) -> 10819934016
A4: Operating income | B4: 76552000 | C4: ='Income Statement '!B16 -> 82964000 | D4: ='Income Statement '!C16 -> 43068000 | E4: ='Income Statement '!D16 -> 73000000 | F4: ='Income Statement '!E16 -> 75100000 | G4: ='Income Statement '!F16 -> 50800000 | H4: =G4/G3*H3 -> 59396433 | I4: =H4/H3*I3 -> 72239196 | J4: =I4/I3*J3 -> 91254078 | K4: =J4/J3*K3 -> 1.1956302e+08 | L4: =K4/K3*L3 -> 1.6227346e+08
A5: Operating Expense | C5: ='Income Statement '!B10 -> 1308638000 | D5: ='Income Statement '!C10 -> 1419032000 | E5: ='Income Statement '!D10 -> 1966300000 | F5: ='Income Statement '!E10 -> 2848800000 | G5: ='Income Statement '!F10 -> 3258300000 | H5: =G5*(1+(G6+($B$12))) -> 3852108019 | I5: =H5*(1+(H6+($B$12))) -> 4702440581 | J5: =I5*(1+(I6+($B$12))) -> 5921523542 | K5: =J5*(1+(J6+($B$12))) -> 7684625997 | L5: =K5*(1+(K6+($B$12))) -> 10268541026
A6: Operating expense yoy % | D6: =(D5-C5)/C5 -> 0.084357935 | E6: =(E5-D5)/D5 -> 0.3856629 | F6: =(F5-E5)/E5 -> 0.44881249 | G6: =(G5-F5)/F5 -> 0.14374473 | H6: =(H5-G5)/G5 -> 0.18224473 | I6: =(I5-H5)/H5 -> 0.22074473 | J6: =(J5-I5)/I5 -> 0.25924473 | K6: =(K5-J5)/J5 -> 0.29774473 | L6: =(L5-K5)/K5 -> 0.33624473
A7: Sales Growth | C7: =(C3-B3)/B3 -> -0.012353479 | D7: =(D3-C3)/C3 -> 0.051789314 | E7: =(E3-D3)/D3 -> 0.38673581 | F7: =(F3-E3)/E3 -> 0.44999039 | G7: =(G3-F3)/F3 -> 0.12222112 | H7: =(H3-G3)/G3 -> 0.16922112 | I7: =(I3-H3)/H3 -> 0.21622112 | J7: =(J3-I3)/I3 -> 0.26322112 | ... L7: =(L3-K3)/K3 -> 0.35722112
A8: Operating Margin | B8: =B4/B3 -> 0.052976503 | C8: =C4/C3 -> 0.05813195 | D8: =D4/D3 -> 0.028691361 | E8: =E4/E3 -> 0.035069178 | F8: =F4/F3 -> 0.024881556 | G8: =G4/G3 -> 0.014997638 | H8: =H4/H3 -> 0.014997638 | I8: =I4/I3 -> 0.014997638 | ... L8: =L4/L3 -> 0.014997638
A11: Assumed Sales growth % each year | B11: 0.047 | D11: =AVERAGE(C7:G7) -> 0.19967663 | F11: =AVERAGE(B8:G8) -> 0.035791364
A12: Assumed Operating expenses % each year | B12: 0.0385
A16: Bega Cheese Limited : Standalone Valuation
B17: Base year | C17: Forecast years
A18: Years | B18: 2023 | C18: 2024E | D18: 2025E | E18: 2026E | F18: 2027E | G18: 2028E | H18: Assumed % | J18: Inputs
A19: Operating Revenue | B19: =G3 -> 3387200000 | C19: =H3 -> 3960385770 | D19: =I3 -> 4816704809 | E19: =J3 -> 6084563233 | F19: =K3 -> 7972123241 | G19: =L3 -> 10819934016 | H19: growth by 4.7% | J19: Tax rate | K19: 0.3
A20: Other Revenue | B20: =23800000 -> 23800000 | C20: =B20*(1+$H$20) -> 27682795 | D20: =C20*(1+$H$20) -> 32199039 | E20: =D20*(1+$H$20) -> 37452075 | F20: =E20*(1+$H$20) -> 43562105 | G20: =F20*(1+$H$20) -> 50668942 | H20: ='Income Statement '!G8 -> 0.16314264 | J20: NWC% | K20: ='Balance Sheet '!K8 -> 0.043264656
A21: Operating Expense | B21: ='Income Statement '!F10 -> 3258300000 | C21: =H5 -> 3852108019 | D21: =I5 -> 4702440581 | E21: =J5 -> 5921523542 | F21: =K5 -> 7684625997 | G21: =L5 -> 10268541026 | H21: shown above | J21: WACC | K21: =WACC!B13 -> 0.057320572
A22: Depreciation | B22: ='Income Statement '!F15*-1 -> 101900000 | C22: ='Balance Sheet '!J15 -> 67750390 | D22: ='Balance Sheet '!K15 -> 62069288 | E22: ='Balance Sheet '!L15 -> 56864566 | F22: ='Balance Sheet '!M15 -> 52096277 | G22: ='Balance Sheet '!O15 -> 47727826 | H22: Check Balance Sheet | J22: CAPEX % | K22: =Cashflow!H18 -> 0.021946663
A23: Operating income | B23: =B19+B20-B21-B22 -> 50800000 | C23: =C19+C20-C21-C22 -> 68210156 | D23: =D19+D20-D21-D22 -> 84393979 | E23: =E19+E20-E21-E22 -> 1.436272e+08 | F23: =F19+F20-F21-F22 -> 2.7896307e+08 | G23: =G19+G20-G21-G22 -> 5.5433411e+08 | J23: Terminal Growth Rate | K23: 0.025
A24: Less taxes | C24: =C23*$K$19 -> 20463047 | D24: =D23*$K$19 -> 25318194 | E24: =E23*$K$19 -> 43088160 | F24: =F23*$K$19 -> 83688921 | G24: =G23*$K$19 -> 1.6630023e+08
A25: NOPAT | C25: =C23-C24 -> 47747109 | D25: =D23-D24 -> 59075785 | E25: =E23-E24 -> 1.0053904e+08 | F25: =F23-F24 -> 1.9527415e+08 | G25: =G23-G24 -> 3.8803387e+08
A26: Add:
A27: Depreciation | B27: =B22 -> 101900000 | C27: =C22 -> 67750390 | D27: =D22 -> 62069288 | E27: =E22 -> 56864566 | F27: =F22 -> 52096277 | G27: =G22 -> 47727826
A28: Less:
A29: Change in NWC | C29: =C46 -> 24798685 | D29: =D46 -> 37048349 | E29: =E46 -> 54853458 | F29: =F46 -> 81664634 | G29: =G46 -> 1.2320955e+08 | H29: WN1
A30: Increase in CAPEX | B30: =Cashflow!G13 -> 71800000 | C30: =C19*$K$22 -> 86917253 | D30: =D19*$K$22 -> 1.057106e+08 | E30: =E19*$K$22 -> 133535861 | F30: =F19*$K$22 -> 174961505 | G30: =G19*$K$22 -> 2.3746145e+08
A31: Free Cash Flow (FCFF) | C31: =C25+C27-C29-C30 -> 3781561 | D31: =D25+D27-D29-D30 -> -21613875 | E31: =E25+E27-E29-E30 -> -30985714 | F31: =F25+F27-F29-F30 -> -9255712.2 | G31: =G25+G27-G29-G30 -> 75090697
A32: Number of Years | B32: 0 | C32: 1 | D32: 2 | E32: 3 | F32: 4 | G32: 5
A33: PV of FCF | C33: =C31/((1+$K$21)^C32) -> 3576551 | D33: =D31/((1+$K$21)^D32) -> -19333891 | E33: =E31/((1+$K$21)^E32) -> -26214493 | F33: =F31/((1+$K$21)^F32) -> -7405989.9 | G33: =G31/((1+$K$21)^G32) -> 56826738 | H33: FCF/(1+WACC)^t
A34: Terminal Value | G34: =G31*(1+K23)/(K21-K23) -> 2381392393 | H34: TV = FCFn*(1+g)/(WACC -g)
A35: Enterprise Value | B35: =SUM(C33:G33,G34) -> 2388841309
A36: Shares Outstanding | B36: 304250000 | F36: Value of debt | G36: =WACC!B30 -> 467100000
A37: Current Price Per Share | B37: 4.42 | C37: Control Premium % | F37: Value of Equity | G37: =B35-G36 -> 1921741309
A38: New Price per share | B38: =B35/B36 -> 7.8515737 | C38: =B39/B37 -> 0.77637415
A39: Acquisition Premium/Control price per share | B39: =B38-B37 -> 3.4315737
A40: Total Acquisition/Control Premium | B40: =B39*B36 -> 1044056309
A43: WN1
A44: Net Working Capital | B44: 2023 | C44: 2024E | D44: =D18 -> 2025E | E44: =E18 -> 2026E | F44: =F18 -> 2027E | G44: =G18 -> 2028E
A45: Working Capital | B45: =B19*$K$20 -> 1.4654604e+08 | C45: =C19*$K$20 -> 1.7134473e+08 | D45: =D19*$K$20 -> 2.0839308e+08 | E45: =E19*$K$20 -> 2.6324653e+08 | F45: =F19*$K$20 -> 3.4491117e+08 | G45: =G19*$K$20 -> 4.6812072e+08
A46: Changes in Working Capital | C46: =C45-B45 -> 24798685 | D46: =D45-C45 -> 37048349 | E46: =E45-D45 -> 54853458 | F46: =F45-E45 -> 81664634 | G46: =G45-F45 -> 1.2320955e+08
A48: Proportion**
...

Sheet Sensitivity Analysis - Sales%
C1: Bega Cheese's Financial Summary and Projections, 2019-2028
B2: 2018 | C2: 2019 | D2: 2020 | E2: 2021 | F2: 2022 | G2: 2023 | H2: 2024E | I2: 2025E | J2: 2026E | K2: 2027E | L2: 2028E
A3: Operating Revenue | B3: 1445018000 | C3: ='Income Statement '!B3 -> 1427167000 | D3: ='Income Statement '!C3 -> 1501079000 | E3: ='Income Statement '!D3 -> 2081600000 | F3: ='Income Statement '!E3 -> 3018300000 | G3: ='Income Statement '!F3 -> 3387200000 | H3: =G3*(1+(G7+$B$11)) -> 3936675370 | I3: =H3*(1+(H7+$B$11)) -> 4732754264 | J3: =I3*(1+(I7+$B$11)) -> 5879127293 | K3: =J3*(1+(J7+$B$11)) -> 7538341169 | L3: =K3*(1+(K7+$B$11)) -> 9967353888
A4: Operating income | B4: 76552000 | C4: ='Income Statement '!B16 -> 82964000 | D4: ='Income Statement '!C16 -> 43068000 | E4: ='Income Statement '!D16 -> 73000000 | F4: ='Income Statement '!E16 -> 75100000 | G4: ='Income Statement '!F16 -> 50800000 | H4: =G4/G3*H3 -> 59040833 | I4: =H4/H3*I3 -> 70980136 | J4: =I4/I3*J3 -> 88173024 | K4: =J4/J3*K3 -> 1.1305731e+08 | L4: =K4/K3*L3 -> 1.4948677e+08
A5: Operating Expense | C5: ='Income Statement '!B10 -> 1308638000 | D5: ='Income Statement '!C10 -> 1419032000 | E5: ='Income Statement '!D10 -> 1966300000 | F5: ='Income Statement '!E10 -> 2848800000 | G5: ='Income Statement '!F10 -> 3258300000 | H5: =G5*(1+(G6+($B$12))) -> 3852108019 | I5: =H5*(1+(H6+($B$12))) -> 4702440581 | J5: =I5*(1+(I6+($B$12))) -> 5921523542 | K5: =J5*(1+(J6+($B$12))) -> 7684625997 | L5: =K5*(1+(K6+($B$12))) -> 10268541026
A6: Operating expense yoy % | D6: =(D5-C5)/C5 -> 0.084357935 | E6: =(E5-D5)/D5 -> 0.3856629 | F6: =(F5-E5)/E5 -> 0.44881249 | G6: =(G5-F5)/F5 -> 0.14374473 | H6: =(H5-G5)/G5 -> 0.18224473 | I6: =(I5-H5)/H5 -> 0.22074473 | J6: =(J5-I5)/I5 -> 0.25924473 | K6: =(K5-J5)/J5 -> 0.29774473 | L6: =(L5-K5)/K5 -> 0.33624473
A7: Sales Growth | C7: =(C3-B3)/B3 -> -0.012353479 | D7: =(D3-C3)/C3 -> 0.051789314 | E7: =(E3-D3)/D3 -> 0.38673581 | F7: =(F3-E3)/E3 -> 0.44999039 | G7: =(G3-F3)/F3 -> 0.12222112 | H7: =(H3-G3)/G3 -> 0.16222112 | I7: =(I3-H3)/H3 -> 0.20222112 | J7: =(J3-I3)/I3 -> 0.24222112 | ... L7: =(L3-K3)/K3 -> 0.32222112
A8: Operating Margin | B8: =B4/B3 -> 0.052976503 | C8: =C4/C3 -> 0.05813195 | D8: =D4/D3 -> 0.028691361 | E8: =E4/E3 -> 0.035069178 | F8: =F4/F3 -> 0.024881556 | G8: =G4/G3 -> 0.014997638 | H8: =H4/H3 -> 0.014997638 | I8: =I4/I3 -> 0.014997638 | ... L8: =L4/L3 -> 0.014997638
A11: Assumed Sales growth % each year | B11: 0.04 | C11: link in gdoc
A12: Assumed Operating expenses % each year | B12: 0.0385 | C12: same proportion op and sales | E12: Been assumed that op expenses follows a similar proportion of the yoy inc in the op revenue
A16: Bega Cheese Limited : Standalone Valuation
B19: Base year | C19: Forecast years
A20: Years | B20: 2023 | C20: 2024E | D20: 2025E | E20: 2026E | F20: 2027E | G20: 2028E | H20: Assumed % | J20: Inputs
A21: Operating Revenue | B21: =G3 -> 3387200000 | C21: =H3 -> 3936675370 | D21: =I3 -> 4732754264 | E21: =J3 -> 5879127293 | F21: =K3 -> 7538341169 | G21: =L3 -> 9967353888 | H21: growth by 4.7% | J21: Tax rate | K21: 0.3
A22: Other Revenue | B22: =23800000 -> 23800000 | C22: =B22*(1+$H$22) -> 27682795 | D22: =C22*(1+$H$22) -> 32199039 | E22: =D22*(1+$H$22) -> 37452075 | F22: =E22*(1+$H$22) -> 43562105 | G22: =F22*(1+$H$22) -> 50668942 | H22: ='Income Statement '!G8 -> 0.16314264 | J22: NWC% | K22: ='Balance Sheet '!K8 -> 0.043264656
A23: Operating Expense | B23: ='Income Statement '!F10 -> 3258300000 | C23: =H5 -> 3852108019 | D23: =I5 -> 4702440581 | E23: =J5 -> 5921523542 | F23: =K5 -> 7684625997 | G23: =L5 -> 10268541026 | H23: shown above | J23: WACC | K23: =WACC!B13 -> 0.057320572
A24: Depreciation | B24: ='Income Statement '!F15*-1 -> 101900000 | C24: ='Balance Sheet '!J15 -> 67750390 | D24: ='Balance Sheet '!K15 -> 62069288 | E24: ='Balance Sheet '!L15 -> 56864566 | F24: ='Balance Sheet '!M15 -> 52096277 | G24: ='Balance Sheet '!O15 -> 47727826 | H24: Check Balance Sheet | J24: CAPEX % | K24: =Cashflow!H18 -> 0.021946663
A25: Operating income | B25: =B21+B22-B23-B24 -> 50800000 | C25: =C21+C22-C23-C24 -> 44499756 | D25: =D21+D22-D23-D24 -> 443434.15 | E25: =E21+E22-E23-E24 -> -61808740 | F25: =F21+F22-F23-F24 -> -154819000 | G25: =G21+G22-G23-G24 -> -298246023 | J25: Terminal Growth Rate | K25: 0.025
A26: Less taxes | C26: =C25*$K$21 -> 13349927 | D26: =D25*$K$21 -> 133030.24 | E26: =E25*$K$21 -> -18542622 | F26: =F25*$K$21 -> -46445700 | G26: =G25*$K$21 -> -89473807
A27: NOPAT | C27: =C25-C26 -> 31149829 | D27: =D25-D26 -> 310403.9 | E27: =E25-E26 -> -43266118 | F27: =F25-F26 -> -108373300 | G27: =G25-G26 -> -2.0877222e+08
A28: Add:
A29: Depreciation | B29: =B24 -> 101900000 | C29: =C24 -> 67750390 | D29: =D24 -> 62069288 | E29: =E24 -> 56864566 | F29: =F24 -> 52096277 | G29: =G24 -> 47727826
A30: Less:
A31: Change in NWC | C31: =C41 -> 23772863 | D31: =D41 -> 34442079 | E31: =E41 -> 49597435 | F31: =F41 -> 71785317 | G31: =G41 -> 1.050904e+08 | H31: WN1
A32: Increase in CAPEX | B32: =Cashflow!G13 -> 71800000 | C32: =C21*$K$24 -> 86396889 | D32: =D21*$K$24 -> 1.0386816e+08 | E32: =E21*$K$24 -> 1.2902723e+08 | F32: =F21*$K$24 -> 1.6544144e+08 | G32: =G21*$K$24 -> 2.1875016e+08
A33: Free Cash Flow (FCFF) | C33: =C27+C29-C31-C32 -> -11269533 | D33: =D27+D29-D31-D32 -> -75930552 | E33: =E27+E29-E31-E32 -> -1.6502621e+08 | F33: =F27+F29-F31-F32 -> -2.9350378e+08 | G33: =G27+G29-G31-G32 -> -4.8488495e+08
A34: Number of Years | B34: 0 | C34: 1 | D34: 2 | E34: 3 | F34: 4 | G34: 5
A35: PV of FCF | C35: =C33/((1+$K$23)^C34) -> -10658577 | D35: =D33/((1+$K$23)^D34) -> -67920863 | E35: =E33/((1+$K$23)^E34) -> -1.3961526e+08 | F35: =F33/((1+$K$23)^F34) -> -2.3484805e+08 | G35: =G33/((1+$K$23)^G34) -> -366948649 | H35: FCF/(1+WACC)^t
A36: Terminal Value | G36: =G33*(1+K25)/(K23-K25) -> -15377421913 | H36: TV = FCFn*(1+g)/(WACC -g)
A37: Enterprise Value | B37: =SUM(C35:G35,G36) -> -16197413314
A39: Net Working Capital | B39: 2023 | C39: 2024E | D39: =D20 -> 2025E | E39: =E20 -> 2026E | F39: =F20 -> 2027E | G39: =G20 -> 2028E
A40: Working Capital | B40: =B21*$K$22 -> 1.4654604e+08 | C40: =C21*$K$22 -> 1.7031891e+08 | D40: =D21*$K$22 -> 2.0476098e+08 | E40: =E21*$K$22 -> 2.5435842e+08 | F40: =F21*$K$22 -> 3.2614374e+08 | G40: =G21*$K$22 -> 4.3123414e+08
A41: Changes in Working Capital | C41: =C40-B40 -> 23772863 | D41: =D40-C40 -> 34442079 | E41: =E40-D40 -> 49597435 | F41: =F40-E40 -> 71785317 | G41: =G40-F40 -> 1.050904e+08
A44: Sensitivity Analysis for Sales Growth Rate
A45: Sales Growth Rate % | B45: FCFF | C45: Enterprise Value
A46: 0.03 | B46: -1.2264931e+09 | C46: -4.0834465e+10
A47: 0.035 | B47: -8.6405426e+08 | C47: -28790448649
A48: 0.04 | B48: FBJND | C48: FDKJNKDFV
A49: 0.045 | B49: -88444528 | C49: -3037718872
A50: 0.046 | B50: -7035579 | C50: -336203993
...

Sheet Sensitivity Analysis - Op exp%
C1: Bega Cheese's Financial Summary and Projections, 2019-2028
B2: 2018 | C2: 2019 | D2: 2020 | E2: 2021 | F2: 2022 | G2: 2023 | H2: 2024E | I2: 2025E | J2: 2026E | K2: 2027E | L2: 2028E
A3: Operating Revenue | B3: 1445018000 | C3: ='Income Statement '!B3 -> 1427167000 | D3: ='Income Statement '!C3 -> 1501079000 | E3: ='Income Statement '!D3 -> 2081600000 | F3: ='Income Statement '!E3 -> 3018300000 | G3: ='Income Statement '!F3 -> 3387200000 | H3: =G3*(1+(G7+$B$11)) -> 3960385770 | I3: =H3*(1+(H7+$B$11)) -> 4816704809 | J3: =I3*(1+(I7+$B$11)) -> 6084563233 | K3: =J3*(1+(J7+$B$11)) -> 7972123241 | L3: =K3*(1+(K7+$B$11)) -> 10819934016
A4: Operating income | B4: 76552000 | C4: ='Income Statement '!B16 -> 82964000 | D4: ='Income Statement '!C16 -> 43068000 | E4: ='Income Statement '!D16 -> 73000000 | F4: ='Income Statement '!E16 -> 75100000 | G4: ='Income Statement '!F16 -> 50800000 | H4: =G4/G3*H3 -> 59396433 | I4: =H4/H3*I3 -> 72239196 | J4: =I4/I3*J3 -> 91254078 | K4: =J4/J3*K3 -> 1.1956302e+08 | L4: =K4/K3*L3 -> 1.6227346e+08
A5: Operating Expense | C5: ='Income Statement '!B10 -> 1308638000 | D5: ='Income Statement '!C10 -> 1419032000 | E5: ='Income Statement '!D10 -> 1966300000 | F5: ='Income Statement '!E10 -> 2848800000 | G5: ='Income Statement '!F10 -> 3258300000 | H5: =G5*(1+(G6+($B$12))) -> 3954744469 | I5: =H5*(1+(H6+($B$12))) -> 5076882389 | J5: =I5*(1+(I6+($B$12))) -> 6872802802 | K5: =J5*(1+(J6+($B$12))) -> 9785116801 | L5: =K5*(1+(K6+($B$12))) -> 14616466700
A6: Operating expense yoy % | D6: =(D5-C5)/C5 -> 0.084357935 | E6: =(E5-D5)/D5 -> 0.3856629 | F6: =(F5-E5)/E5 -> 0.44881249 | G6: =(G5-F5)/F5 -> 0.14374473 | H6: =(H5-G5)/G5 -> 0.21374473 | I6: =(I5-H5)/H5 -> 0.28374473 | J6: =(J5-I5)/I5 -> 0.35374473 | K6: =(K5-J5)/J5 -> 0.42374473 | L6: =(L5-K5)/K5 -> 0.49374473
A7: Sales Growth | C7: =(C3-B3)/B3 -> -0.012353479 | D7: =(D3-C3)/C3 -> 0.051789314 | E7: =(E3-D3)/D3 -> 0.38673581 | F7: =(F3-E3)/E3 -> 0.44999039 | G7: =(G3-F3)/F3 -> 0.12222112 | H7: =(H3-G3)/G3 -> 0.16922112 | I7: =(I3-H3)/H3 -> 0.21622112 | J7: =(J3-I3)/I3 -> 0.26322112 | ... L7: =(L3-K3)/K3 -> 0.35722112
A8: Operating Margin | B8: =B4/B3 -> 0.052976503 | C8: =C4/C3 -> 0.05813195 | D8: =D4/D3 -> 0.028691361 | E8: =E4/E3 -> 0.035069178 | F8: =F4/F3 -> 0.024881556 | G8: =G4/G3 -> 0.014997638 | H8: =H4/H3 -> 0.014997638 | I8: =I4/I3 -> 0.014997638 | ... L8: =L4/L3 -> 0.014997638
A11: Assumed Sales growth % each year | B11: 0.047 | C11: link in gdoc
A12: Assumed Operating expenses % each year | B12: 0.07 | C12: same proportion op & sales | E12: Been assumed that op expenses follows a similar proportion of the yoy inc in the op revenue
A16: Bega Cheese Limited : Standalone Valuation
B19: Base year | C19: Forecast years
A20: Years | B20: 2023 | C20: 2024E | D20: 2025E | E20: 2026E | F20: 2027E | G20: 2028E | H20: Assumed % | J20: Inputs
A21: Operating Revenue | B21: =G3 -> 3387200000 | C21: =H3 -> 3960385770 | D21: =I3 -> 4816704809 | E21: =J3 -> 6084563233 | F21: =K3 -> 7972123241 | G21: =L3 -> 10819934016 | H21: growth by 4.7% | J21: Tax rate | K21: 0.3
A22: Other Revenue | B22: =23800000 -> 23800000 | C22: =B22*(1+$H$22) -> 27682795 | D22: =C22*(1+$H$22) -> 32199039 | E22: =D22*(1+$H$22) -> 37452075 | F22: =E22*(1+$H$22) -> 43562105 | G22: =F22*(1+$H$22) -> 50668942 | H22: ='Income Statement '!G8 -> 0.16314264 | J22: NWC% | K22: ='Balance Sheet '!K8 -> 0.043264656
A23: Operating Expense | B23: ='Income Statement '!F10 -> 3258300000 | C23: =H5 -> 3954744469 | D23: =I5 -> 5076882389 | E23: =J5 -> 6872802802 | F23: =K5 -> 9785116801 | G23: =L5 -> 14616466700 | H23: shown above | J23: WACC | K23: =WACC!B13 -> 0.057320572
A24: Depreciation | B24: ='Income Statement '!F15*-1 -> 101900000 | C24: ='Balance Sheet '!J15 -> 67750390 | D24: ='Balance Sheet '!K15 -> 62069288 | E24: ='Balance Sheet '!L15 -> 56864566 | F24: ='Balance Sheet '!M15 -> 52096277 | G24: ='Balance Sheet '!O15 -> 47727826 | H24: Check Balance Sheet | J24: CAPEX % | K24: =Cashflow!H18 -> 0.021946663
A25: Operating income | B25: =B21+B22-B23-B24 -> 50800000 | C25: =C21+C22-C23-C24 -> -34426294 | D25: =D21+D22-D23-D24 -> -2.9004783e+08 | E25: =E21+E22-E23-E24 -> -8.0765206e+08 | F25: =F21+F22-F23-F24 -> -1821527733 | G25: =G21+G22-G23-G24 -> -3793591568 | J25: Terminal Growth Rate | K25: 0.025
A26: Less taxes | C26: =C25*$K$21 -> -10327888 | D26: =D25*$K$21 -> -87014349 | E26: =E25*$K$21 -> -2.4229562e+08 | F26: =F25*$K$21 -> -5.4645832e+08 | G26: =G25*$K$21 -> -1138077470
A27: NOPAT | C27: =C25-C26 -> -24098406 | D27: =D25-D26 -> -2.0303348e+08 | E27: =E25-E26 -> -5.6535644e+08 | F27: =F25-F26 -> -1275069413 | G27: =G25-G26 -> -2655514097
A28: Add:
A29: Depreciation | B29: =B24 -> 101900000 | C29: =C24 -> 67750390 | D29: =D24 -> 62069288 | E29: =E24 -> 56864566 | F29: =F24 -> 52096277 | G29: =G24 -> 47727826
A30: Less:
A31: Change in NWC | C31: =C41 -> 24798685 | D31: =D41 -> 37048349 | E31: =E41 -> 54853458 | F31: =F41 -> 81664634 | G31: =G41 -> 1.2320955e+08 | H31: WN1
A32: Increase in CAPEX | B32: =Cashflow!G13 -> 71800000 | C32: =C21*$K$24 -> 86917253 | D32: =D21*$K$24 -> 1.057106e+08 | E32: =E21*$K$24 -> 133535861 | F32: =F21*$K$24 -> 174961505 | G32: =G21*$K$24 -> 2.3746145e+08
A33: Free Cash Flow (FCFF) | C33: =C27+C29-C31-C32 -> -68063954 | D33: =D27+D29-D31-D32 -> -2.8372314e+08 | E33: =E27+E29-E31-E32 -> -6.968812e+08 | F33: =F27+F29-F31-F32 -> -1479599275 | G33: =G27+G29-G31-G32 -> -2968457274
A34: Number of Years | B34: 0 | C34: 1 | D34: 2 | E34: 3 | F34: 4 | G34: 5
A35: PV of FCF | C35: =C33/((1+$K$23)^C34) -> -64374000 | D35: =D33/((1+$K$23)^D34) -> -2.5379402e+08 | E35: =E33/((1+$K$23)^E34) -> -5.8957451e+08 | F35: =F33/((1+$K$23)^F34) -> -1183906434 | G35: =G33/((1+$K$23)^G34) -> -2246453280 | H35: FCF/(1+WACC)^t
A36: Terminal Value | G36: =G33*(1+K25)/(K23-K25) -> -94140310893 | H36: TV = FCFn*(1+g)/(WACC -g)
A37: Enterprise Value | B37: =SUM(C35:G35,G36) -> -98478413142
A38: WN1
A39: Net Working Capital | B39: 2023 | C39: 2024E | D39: =D20 -> 2025E | E39: =E20 -> 2026E | F39: =F20 -> 2027E | G39: =G20 -> 2028E
A40: Working Capital | B40: =B21*$K$22 -> 1.4654604e+08 | C40: =C21*$K$22 -> 1.7134473e+08 | D40: =D21*$K$22 -> 2.0839308e+08 | E40: =E21*$K$22 -> 2.6324653e+08 | F40: =F21*$K$22 -> 3.4491117e+08 | G40: =G21*$K$22 -> 4.6812072e+08
A41: Changes in Working Capital | C41: =C40-B40 -> 24798685 | D41: =D40-C40 -> 37048349 | E41: =E40-D40 -> 54853458 | F41: =F40-E40 -> 81664634 | G41: =G40-F40 -> 1.2320955e+08
A44: Sensitivity Analysis for Operating expenses %
A45: Operating Expenses % | B45: FCFF | C45: Enterprise Value
A46: 0.03 | B46: 7.6281384e+08 | C46: 25226814282
A47: 0.035 | B47: 3.6465442e+08 | C47: 1.2002164e+10
A48: 0.038 | B48: 117013420 | C48: 3.78043e+09
A49: 0.0385 | B49: 75090697 | C49: 2.3888413e+09
...

Sheet Sensitivity Analysis - WACC
C1: Bega Cheese's Financial Summary and Projections, 2019-2028
B2: 2018 | C2: 2019 | D2: 2020 | E2: 2021 | F2: 2022 | G2: 2023 | H2: 2024E | I2: 2025E | J2: 2026E | K2: 2027E | L2: 2028E
A3: Operating Revenue | B3: 1445018000 | C3: ='Income Statement '!B3 -> 1427167000 | D3: ='Income Statement '!C3 -> 1501079000 | E3: ='Income Statement '!D3 -> 2081600000 | F3: ='Income Statement '!E3 -> 3018300000 | G3: ='Income Statement '!F3 -> 3387200000 | H3: =G3*(1+(G7+$B$11)) -> 3960385770 | I3: =H3*(1+(H7+$B$11)) -> 4816704809 | J3: =I3*(1+(I7+$B$11)) -> 6084563233 | K3: =J3*(1+(J7+$B$11)) -> 7972123241 | L3: =K3*(1+(K7+$B$11)) -> 10819934016
A4: Operating income | B4: 76552000 | C4: ='Income Statement '!B16 -> 82964000 | D4: ='Income Statement '!C16 -> 43068000 | E4: ='Income Statement '!D16 -> 73000000 | F4: ='Income Statement '!E16 -> 75100000 | G4: ='Income Statement '!F16 -> 50800000 | H4: =G4/G3*H3 -> 59396433 | I4: =H4/H3*I3 -> 72239196 | J4: =I4/I3*J3 -> 91254078 | K4: =J4/J3*K3 -> 1.1956302e+08 | L4: =K4/K3*L3 -> 1.6227346e+08
A5: Operating Expense | C5: ='Income Statement '!B10 -> 1308638000 | D5: ='Income Statement '!C10 -> 1419032000 | E5: ='Income Statement '!D10 -> 1966300000 | F5: ='Income Statement '!E10 -> 2848800000 | G5: ='Income Statement '!F10 -> 3258300000 | H5: =G5*(1+(G6+($B$12))) -> 3852108019 | I5: =H5*(1+(H6+($B$12))) -> 4702440581 | J5: =I5*(1+(I6+($B$12))) -> 5921523542 | K5: =J5*(1+(J6+($B$12))) -> 7684625997 | L5: =K5*(1+(K6+($B$12))) -> 10268541026
A6: Operating expense yoy % | D6: =(D5-C5)/C5 -> 0.084357935 | E6: =(E5-D5)/D5 -> 0.3856629 | F6: =(F5-E5)/E5 -> 0.44881249 | G6: =(G5-F5)/F5 -> 0.14374473 | H6: =(H5-G5)/G5 -> 0.18224473 | I6: =(I5-H5)/H5 -> 0.22074473 | J6: =(J5-I5)/I5 -> 0.25924473 | K6: =(K5-J5)/J5 -> 0.29774473 | L6: =(L5-K5)/K5 -> 0.33624473
A7: Sales Growth | C7: =(C3-B3)/B3 -> -0.012353479 | D7: =(D3-C3)/C3 -> 0.051789314 | E7: =(E3-D3)/D3 -> 0.38673581 | F7: =(F3-E3)/E3 -> 0.44999039 | G7: =(G3-F3)/F3 -> 0.12222112 | H7: =(H3-G3)/G3 -> 0.16922112 | I7: =(I3-H3)/H3 -> 0.21622112 | J7: =(J3-I3)/I3 -> 0.26322112 | ... L7: =(L3-K3)/K3 -> 0.35722112
A8: Operating Margin | B8: =B4/B3 -> 0.052976503 | C8: =C4/C3 -> 0.05813195 | D8: =D4/D3 -> 0.028691361 | E8: =E4/E3 -> 0.035069178 | F8: =F4/F3 -> 0.024881556 | G8: =G4/G3 -> 0.014997638 | H8: =H4/H3 -> 0.014997638 | I8: =I4/I3 -> 0.014997638 | ... L8: =L4/L3 -> 0.014997638
A11: Assumed Sales growth % each year | B11: 0.047 | C11: link in gdoc
A12: Assumed Operating expenses % each year | B12: 0.0385 | C12: ame proportion op & sales | E12: Been assumed that op expenses follows a similar proportion of the yoy inc in the op revenue
A16: Bega Cheese Limited : Standalone Valuation
B19: Base year | C19: Forecast years
A20: Years | B20: 2023 | C20: 2024E | D20: 2025E | E20: 2026E | F20: 2027E | G20: 2028E | H20: Assumed % | J20: Inputs
A21: Operating Revenue | B21: =G3 -> 3387200000 | C21: =H3 -> 3960385770 | D21: =I3 -> 4816704809 | E21: =J3 -> 6084563233 | F21: =K3 -> 7972123241 | G21: =L3 -> 10819934016 | H21: growth by 4.7% | J21: Tax rate | K21: 0.3
A22: Other Revenue | B22: =23800000 -> 23800000 | C22: =B22*(1+$H$22) -> 27682795 | D22: =C22*(1+$H$22) -> 32199039 | E22: =D22*(1+$H$22) -> 37452075 | F22: =E22*(1+$H$22) -> 43562105 | G22: =F22*(1+$H$22) -> 50668942 | H22: ='Income Statement '!G8 -> 0.16314264 | J22: NWC% | K22: ='Balance Sheet '!K8 -> 0.043264656
A23: Operating Expense | B23: ='Income Statement '!F10 -> 3258300000 | C23: =H5 -> 3852108019 | D23: =I5 -> 4702440581 | E23: =J5 -> 5921523542 | F23: =K5 -> 7684625997 | G23: =L5 -> 10268541026 | H23: shown above | J23: WACC | K23: 0.06
A24: Depreciation | B24: ='Income Statement '!F15*-1 -> 101900000 | C24: ='Balance Sheet '!J15 -> 67750390 | D24: ='Balance Sheet '!K15 -> 62069288 | E24: ='Balance Sheet '!L15 -> 56864566 | F24: ='Balance Sheet '!M15 -> 52096277 | G24: ='Balance Sheet '!O15 -> 47727826 | H24: Check Balance Sheet | J24: CAPEX % | K24: =Cashflow!H18 -> 0.021946663
A25: Operating income | B25: =B21+B22-B23-B24 -> 50800000 | C25: =C21+C22-C23-C24 -> 68210156 | D25: =D21+D22-D23-D24 -> 84393979 | E25: =E21+E22-E23-E24 -> 1.436272e+08 | F25: =F21+F22-F23-F24 -> 2.7896307e+08 | G25: =G21+G22-G23-G24 -> 5.5433411e+08 | J25: Terminal Growth Rate | K25: 0.025
A26: Less taxes | C26: =C25*$K$21 -> 20463047 | D26: =D25*$K$21 -> 25318194 | E26: =E25*$K$21 -> 43088160 | F26: =F25*$K$21 -> 83688921 | G26: =G25*$K$21 -> 1.6630023e+08
A27: NOPAT | C27: =C25-C26 -> 47747109 | D27: =D25-D26 -> 59075785 | E27: =E25-E26 -> 1.0053904e+08 | F27: =F25-F26 -> 1.9527415e+08 | G27: =G25-G26 -> 3.8803387e+08
A28: Add:
A29: Depreciation | B29: =B24 -> 101900000 | C29: =C24 -> 67750390 | D29: =D24 -> 62069288 | E29: =E24 -> 56864566 | F29: =F24 -> 52096277 | G29: =G24 -> 47727826
A30: Less:
A31: Change in NWC | C31: =C49 -> 24798685 | D31: =D49 -> 37048349 | E31: =E49 -> 54853458 | F31: =F49 -> 81664634 | G31: =G49 -> 1.2320955e+08 | H31: WN1
A32: Increase in CAPEX | B32: =Cashflow!G13 -> 71800000 | C32: =C21*$K$24 -> 86917253 | D32: =D21*$K$24 -> 1.057106e+08 | E32: =E21*$K$24 -> 133535861 | F32: =F21*$K$24 -> 174961505 | G32: =G21*$K$24 -> 2.3746145e+08
A33: Free Cash Flow (FCFF) | C33: =C27+C29-C31-C32 -> 3781561 | D33: =D27+D29-D31-D32 -> -21613875 | E33: =E27+E29-E31-E32 -> -30985714 | F33: =F27+F29-F31-F32 -> -9255712.2 | G33: =G27+G29-G31-G32 -> 75090697
A34: Number of Years | B34: 0 | C34: 1 | D34: 2 | E34: 3 | F34: 4 | G34: 5
A35: PV of FCF | C35: =C33/((1+$K$23)^C34) -> 3567510.4 | D35: =D33/((1+$K$23)^D34) -> -19236271 | E35: =E33/((1+$K$23)^E34) -> -26016203 | F35: =F33/((1+$K$23)^F34) -> -7331391 | G35: =G33/((1+$K$23)^G34) -> 56112137 | H35: FCF/(1+WACC)^t
A36: Terminal Value | G36: =G33*(1+K25)/(K23-K25) -> 2199084702 | H36: TV = FCFn*(1+g)/(WACC -g)
A37: Enterprise Value | B37: =SUM(C35:G35,G36) -> 2206180484
A38: Shares Outstanding | B38: 304250000 | F38: Value of debt | G38: =WACC!B30 -> 467100000
A39: Old Price Per Share | B39: ='Relative Valuation'!B8 -> 2.85 | C39: Control Premium % | F39: Value of Equity | G39: =B37-G38 -> 1739080484
A40: New Price per share | B40: =B37/B38 -> 7.2512095 | C40: =(B39/B40) -> 0.39303788
A41: Acquisition Premium price per share | B41: =B40-B39 -> 4.4012095
A42: Acquisition Premium | B42: =B41*B38 -> 1339067984
A46: WN1
A47: Net Working Capital | B47: 2023 | C47: 2024E | D47: =D20 -> 2025E | E47: =E20 -> 2026E | F47: =F20 -> 2027E | G47: =G20 -> 2028E
A48: Working Capital | B48: =B21*$K$22 -> 1.4654604e+08 | C48: =C21*$K$22 -> 1.7134473e+08 | D48: =D21*$K$22 -> 2.0839308e+08 | E48: =E21*$K$22 -> 2.6324653e+08 | F48: =F21*$K$22 -> 3.4491117e+08 | G48: =G21*$K$22 -> 4.6812072e+08
A49: Changes in Working Capital | C49: =C48-B48 -> 24798685 | D49: =D48-C48 -> 37048349 | E49: =E48-D48 -> 54853458 | F49: =F48-E48 -> 81664634 | G49: =G48-F48 -> 1.2320955e+08
A51: Sensitivity Analysis for WACC
...

Sheet Relative Valuation
E1: RELATIVE VALUATION
A2: 2023 Values from MorningStar | Q2: (based on mkt cap)
A3: Companies | B3: Share Price | C3: Share Outstanding | D3: EPS | E3: Market Cap | F3: Net Income | G3: Revenue | H3: EBITDA | I3: Enterprise Value | J3: P/E | K3: P/B | L3: EV/EBITDA | M3: EV/EBIT | N3: EV/Revenue | O3: MV /Revenue | P3: MV/ Net Income | Q3: Weights Assumed
A4: Ridley Corporation Limited | B4: 2.17 | C4: 315830000 | D4: 13.24 | E4: 631670000 | F4: 637200000 | G4: 1260133000 | H4: 88500000 | I4: 669810000 | J4: =B4/D4 -> 0.16389728 | K4: 2 | L4: =I4/H4 -> 7.5684746 | M4: =I4/F4 -> 1.051177 | N4: =I4/G4 -> 0.53153913 | O4: =E4/G4 -> 0.50127248 | P4: =E4/F4 -> 0.99132141 | Q4: =E4/$E$9 -> 0.094892792
A5: A2 Milk Company | B5: 6.24 | C5: 721980000 | D5: 19.24 | E5: 4511000000 | F5: 184890000 | G5: 1461993935 | H5: 201620000 | I5: 2886610000 | J5: =B5/D5 -> 0.32432432 | K5: 3.34 | L5: 14.32 | M5: =I5/F5 -> 15.61258 | N5: =I5/G5 -> 1.9744336 | O5: =E5/G5 -> 3.0855121 | P5: =E5/F5 -> 24.398291 | Q5: =E5/$E$9 -> 0.67766616
A6: FFI Holdings Limited | B6: 4.19 | C6: 10680000 | D6: 16.2 | E6: 45000000 | F6: 2281740 | G6: 46793870 | H6: 3212660 | I6: 36120000 | J6: =E6/F6 -> 19.721791 | K6: 0.88 | L6: 11.24 | M6: =I6/F6 -> 15.830024 | N6: =E6/G6 -> 0.96166442 | O6: =E6/G6 -> 0.96166442 | P6: =E6/F6 -> 19.721791 | Q6: =E6/$E$9 -> 0.0067601368
A7: Bubs Australia Limited | B7: 0.15 | C7: 739270000 | D7: -14.66 | E7: 134000000 | F7: -71385971 | G7: 60110627 | H7: -67382191 | I7: 111420000 | J7: =E7/F7 -> -1.8771195 | K7: 3.19 | L7: =I7/H7 -> -1.6535526 | M7: =I7/F7 -> -1.5608109 | N7: =I7/G7 -> 1.8535824 | O7: =E7/G7 -> 2.2292231 | P7: =E7/F7 -> -1.8771195 | Q7: =E7/$E$9 -> 0.020130185
A8: Bega Cheese | B8: 2.85 | C8: 304250000 | D8: -75.6 | E8: 1335000000 | F8: ='Income Statement '!F19 -> 24100000 | G8: ='Income Statement '!F3 -> 3387200000 | H8: ='Income Statement '!F19+('Income Statement '!F18*-1) -> 48200000 | I8: 1267810000 | J8: =B8/D8 -> -0.037698413 | K8: 0.86 | L8: =I8/H8 -> 26.303112 | M8: =I8/F8 -> 52.606224 | N8: =I8/G8 -> 0.3742944 | O8: =E8/G8 -> 0.39413085 | P8: =E8/F8 -> 55.394191 | Q8: =E8/$E$9 -> 0.20055073
D9: Total Market Cap | E9: =SUM(E4:E8) -> 6656670000 | J9: =AVERAGE(J4:J8) -> 3.659039 | K9: =AVERAGE(K4:K8) -> 2.054 | L9: =AVERAGE(L4:L8) -> 11.555607 | M9: =AVERAGE(M4:M8) -> 16.707839 | N9: =AVERAGE(N4:N8) -> 1.1391028 | O9: =AVERAGE(O4:O8) -> 1.4343606 | P9: =AVERAGE(P4:P8) -> 19.725695 | Q9: =SUM(Q4:Q8) -> 1
A11: Companies | B11: Weights | C11: Weighted EV/EBITDA | D11: Weighted EV/EBIT | E11: Weighted EV/Revenue
A12: Ridley Corporation Limited | B12: =Q4 -> 0.094892792 | C12: =$B$12*L4 -> 0.71819368 | D12: =$B$12*M4 -> 0.099749122 | E12: =$B$12*N4 -> 0.050439232
A13: A2 Milk Company | B13: =Q5 -> 0.67766616 | C13: =$B$13*L5 -> 9.7041794 | D13: =$B$13*M5 -> 10.580117 | E13: =$B$13*N5 -> 1.3380069
A14: FFI Holdings Limited | B14: =Q6 -> 0.0067601368 | C14: =$B$14*L6 -> 0.075983938 | D14: =$B$14*M6 -> 0.10701313 | E14: =$B$14*N6 -> 0.0065009831
A15: Bubs Australia Limited | B15: =Q7 -> 0.020130185 | C15: =$B$15*L7 -> -0.033286321 | D15: =$B$15*M7 -> -0.031419412 | E15: =$B$15*N7 -> 0.037312957
A16: Bega Cheese | B16: =Q8 -> 0.20055073 | C16: =$B$16*L8 -> 5.2751082 | D16: =$B$16*M8 -> 10.550216 | E16: =$B$16*N8 -> 0.075065014
A18: SUM | B18: =SUM(B12:B16) -> 1 | C18: =SUM(C12:C16) -> 15.740179 | D18: =SUM(D12:D16) -> 21.305677 | E18: =SUM(E12:E16) -> 1.507325
A20: Enterprise Value | C20: =C18*H8 -> 7.5867662e+08 | D20: =D18*F8 -> 5.1346681e+08 | E20: =E18*G8 -> 5105611399
C21: AVERAGE (EV) | E21: =AVERAGE(C20:E20) -> 2125918277
C22: Price per share | E22: =E21/C8 -> 6.987406
C23: Acquisition premium per share | E23: =E22-B8 -> 4.137406
C24: Acquisition premium | E24: =E23*C8 -> 1258805777

Sheet Synergy Valuation
B1: Bega Cheese Limited Valuation with Synergy
B3: Base Year | C3: Forecast Years
B4: 2023 | C4: 2024E | D4: 2025E | E4: 2026E | F4: 2027E | G4: 2028E | I4: Inputs
A5: Year | B5: 0 | C5: 1 | D5: 2 | E5: 3 | F5: 4 | G5: 5 | H5: Assumptions | I5: Tax Rate | J5: 0.3
A6: Operating Income | B6: ='Fundamental Valuation'!B23 -> 50800000 | C6: ='Fundamental Valuation'!C23*(1+$H$6) -> 75031172 | D6: ='Fundamental Valuation'!D23*(1+$H$6) -> 92833376 | E6: ='Fundamental Valuation'!E23*(1+$H$6) -> 1.5798992e+08 | F6: ='Fundamental Valuation'!F23*(1+$H$6) -> 3.0685938e+08 | G6: ='Fundamental Valuation'!G23*(1+$H$6) -> 6.0976752e+08 | H6: 0.1 | I6: WACC BGA | J6: =WACC!B13 -> 0.057320572
A7: Cost Savings | B7: 0 | C7: =$H$7*'Fundamental Valuation'!C21 -> 77042160 | D7: =$H$7*'Fundamental Valuation'!D21 -> 94048812 | E7: =$H$7*'Fundamental Valuation'!E21 -> 1.1843047e+08 | F7: =$H$7*'Fundamental Valuation'!F21 -> 1.5369252e+08 | G7: =$H$7*'Fundamental Valuation'!G21 -> 2.0537082e+08 | H7: 0.02 | I7: WACC WOW | J7: =WACC!F13 -> 0.042773792
A8: Integration Costs | C8: -50000000 | D8: -50000000 | I8: Terminal Growth | J8: ='Fundamental Valuation'!K23 -> 0.025
A9: Operating Income + Synergies | C9: =SUM(C6:C8) -> 1.0207333e+08 | D9: =SUM(D6:D8) -> 136882188 | E9: =SUM(E6:E8) -> 2.7642039e+08 | F9: =SUM(F6:F8) -> 4.605519e+08 | G9: =SUM(G6:G8) -> 8.1513834e+08
A10: Taxes | C10: =C9*$J$5 -> 30622000 | D10: =D9*$J$5 -> 41064656 | E10: =E9*$J$5 -> 82926117 | F10: =F9*$J$5 -> 1.3816557e+08 | G10: =G9*$J$5 -> 244541501
A11: NOPAT | C11: =C9-C10 -> 71451333 | D11: =D9-D10 -> 95817532 | E11: =E9-E10 -> 1.9349427e+08 | F11: =F9-F10 -> 3.2238633e+08 | G11: =G9-G10 -> 5.7059684e+08
A12: Add: | I12: Average of Valuations
A13: Depreciation | C13: ='Balance Sheet '!J15 -> 67750390 | D13: ='Balance Sheet '!K15 -> 62069288 | E13: ='Balance Sheet '!L15 -> 56864566 | F13: ='Balance Sheet '!M15 -> 52096277 | G13: ='Balance Sheet '!O15 -> 47727826 | I13: Standalone Valuation | J13: ='Fundamental Valuation'!B35 -> 2388841309
A14: Less: | I14: Synergy Valuation | J14: =B20 -> 15262245734 | K14: Average EV Valuation
A15: Change in NWC | C15: ='Fundamental Valuation'!C29 -> 24798685 | D15: ='Fundamental Valuation'!D29 -> 37048349 | E15: ='Fundamental Valuation'!E29 -> 54853458 | F15: ='Fundamental Valuation'!F29 -> 81664634 | G15: ='Fundamental Valuation'!G29 -> 1.2320955e+08 | I15: Multiples Valuation | J15: ='Relative Valuation'!E21 -> 2125918277 | K15: Price per share | L15: Acquisition Premium per share
A16: Capital Expenditures | C16: ='Fundamental Valuation'!C30 -> 86917253 | D16: ='Fundamental Valuation'!D30 -> 1.057106e+08 | E16: ='Fundamental Valuation'!E30 -> 133535861 | F16: ='Fundamental Valuation'!F30 -> 174961505 | G16: ='Fundamental Valuation'!G30 -> 2.3746145e+08 | I16: Average | J16: =AVERAGE(J13:J15) -> 6592335107 | K16: =J16/J22 -> 21.667494 | L16: =K16-J21 -> 17.247494
A17: FCFF | C17: =C11+C13-C15-C16 -> 27485784 | D17: =D11+D13-D15-D16 -> 15127872 | E17: =E11+E13-E15-E16 -> 61969520 | F17: =F11+F13-F15-F16 -> 1.1785647e+08 | G17: =G11+G13-G15-G16 -> 2.5765366e+08
A18: PV of FCFF | C18: =C17/(1+$J$7)^C5 -> 26358338 | D18: =D17/(1+$J$7)^D5 -> 13912258 | E18: =E17/(1+$J$7)^E5 -> 54652220 | F18: =F17/(1+$J$7)^F5 -> 99676548 | G18: =G17/(1+$J$7)^G5 -> 2.0897088e+08 | I18: Comparing Standalone vs. Synergy Valuation
A19: Terminal Value | G19: =G17*(1+J8)/(J7-J8) -> 14858675487 | J19: Without Synergy | K19: With Synergy
A20: Enterprise Value | B20: =SUM(C18:G18,G19) -> 15262245734 | I20: Enterprise Value | J20: ='Fundamental Valuation'!B35 -> 2388841309 | K20: =B20 -> 15262245734
I21: Current Market Price | J21: 4.42 | K21: 4.42
I22: Shares Outstanding | J22: 304250000 | K22: 304250000
I23: Price per share | J23: =J20/J22 -> 7.8515737 | K23: =K20/K22 -> 50.163503
I24: Acquisition premium per share | J24: =J23-J21 -> 3.4315737 | K24: =K23-K21 -> 45.743503

Sheet Deal Structure
B3: Comparison of Enterprise Value under different methods
C4: Standalone Valuation | E4: Synergy Valuation | F4: Multiples Valuation
B5: Enterprise Value | C5: ='Fundamental Valuation'!B35 -> 2388841309 | E5: ='Synergy Valuation'!B20 -> 15262245734 | F5: ='Relative Valuation'!E21 -> 2125918277
B6: Average Value | C6: =AVERAGE(C5:F5) -> 6592335107
B9: Deal Structure
E10: Before Acquisition | F10: After Acquisition
B11: Total Acquisition Cost | C11: =C6 -> 6592335107 | D11: Debt | E11: =WACC!F28 -> 14660000000 | F11: =F17+E11 -> 16637700532
B12: Assumed Cash split % | C12: 0.3 | D12: Equity | E12: =WACC!F29 -> 6565000000 | F12: =E12+C15 -> 11179634575
B13: Assumed equity split % | C13: =1-C12 -> 0.7 | D13: Cash | E13: 1135000000 | F13: =E13-C14 -> -842700532
B14: Cash component | C14: =C12*C11 -> 1977700532 | D14: D/E | E14: =E11/E12 -> 2.2330541 | F14: =F11/F12 -> 1.4882151
B15: Equity component | C15: =C13*C11 -> 4614634575
B16: No. of shares issued | C16: =C15/C17 -> 1044034972
B17: Current share price | C17: 4.42 | D17: Assuming new debt | F17: =C14 -> 1977700532

Sheet Cashflow
A1: Data Sourced from : MorningStar
A2: Item | B2: 43617 | C2: 43983 | D2: 44348 | E2: 44713 | F2: 45078
A3: Operating Cash Flow
A4: Receipts from Customers | B4: 1422126000 | C4: 1691644000 | D4: 2221700000 | E4: 3342800000 | F4: 3611100000
A5: Payments to Suppliers and Employees | B5: -1476828000 | C5: -1494944000 | D5: -2086500000 | E5: -3179200000 | F5: -3607800000
A6: Dividends Received | B6: 0 | C6: 0 | D6: 0 | E6: 0 | F6: 0
A7: Interest Received | B7: 0 | C7: 0 | D7: 100000 | E7: 100000 | F7: 1000000
A8: Interest Paid | B8: -20363000 | C8: -11280000 | D8: -10500000 | E8: -12500000 | F8: -24100000
A9: Tax Paid | B9: -13264000 | C9: -12330000 | D9: -700000 | E9: -11900000 | F9: -8600000
A10: Other Operating Cashflows | B10: 188601000 | C10: -35359000 | D10: -12700000 | E10: 18900000 | F10: 36600000
A11: Net Operating Cashflows | B11: 100272000 | C11: 137731000 | D11: 111400000 | E11: 158200000 | F11: 8200000
A12: Investing Cashflow | G12: CAPEX 2022 | H12: CAPEX 2023
A13: Payment for Purchase of PPE | B13: -62349000 | C13: -56837000 | D13: -32200000 | E13: -71800000 | F13: -68100000 | G13: =(E13+E15+E17)*-1 -> 71800000 | H13: =(F13+F15+F17)*-1 -> 68100000
A14: Proceeds From Sale of PPE | B14: 203000 | C14: 4952000 | D14: 0 | E14: 7000000 | F14: 116100000 | G14: Operating Revenue 2022 | H14: Operating Revenue 2023
A15: Investments Purchased | B15: -30325000 | C15: -1000000 | D15: 0 | E15: 0 | F15: 0 | G15: 3018300000 | H15: 3387200000
A16: Proceeds From Sale of Investments | B16: 30981000 | C16: 0 | D16: 0 | E16: 0 | F16: 51000000 | G16: CAPEX to Sales %
A17: Payments for Purchase of Subsidiaries | B17: -251173000 | C17: 0 | D17: -514500000 | E17: 0 | F17: 0 | G17: =G13/G15 -> 0.023788225 | H17: =H13/H15 -> 0.020105102
A18: Proceeds from Sale of Subsidiaries | B18: 0 | C18: 0 | D18: 0 | E18: 1000000 | F18: 0 | G18: Average CAPEX % | H18: =AVERAGE(G17:H17) -> 0.021946663
A19: Loans Granted | B19: 0 | C19: 0 | D19: 0 | E19: 0 | F19: 0
A20: Loans Repaid | B20: 0 | C20: 0 | D20: 0 | E20: 0 | F20: 0
A21: Other Investing Cashflows | B21: -10218000 | C21: 309000 | D21: 0 | E21: 0 | F21: 900000
A22: Net Investing Cashflows | B22: -322881000 | C22: -52576000 | D22: -546700000 | E22: -63800000 | F22: 99900000
A23: Financing Cashflows
A24: Proceeds from Issues | B24: 199859000 | C24: 0 | D24: 390200000 | E24: 0 | F24: 0
A25: Proceeds from Borrowings | B25: 395083000 | C25: 18202000 | D25: 205000000 | E25: 310000000 | F25: 0
A26: Repayment of Borrowings | B26: -346011000 | C26: -87000000 | D26: -60000000 | E26: -393000000 | F26: -40000000
A27: Dividends Paid | B27: -19127000 | C27: -19455000 | D27: -23300000 | E27: -28700000 | F27: -26800000
A28: Other Financing Cashflows | B28: -104000 | C28: -2780000 | D28: -12300000 | E28: -25000000 | F28: -19800000
A29: Net Financing Cashflows | B29: 229700000 | C29: -91033000 | D29: 499600000 | E29: -136700000 | F29: -86600000
A30: Net Increase in Cash | B30: 7091000 | C30: -5878000 | D30: 64300000 | E30: -42300000 | F30: 21500000
A31: Cash at Beginning of Period | B31: 21669000 | C31: 28760000 | D31: 22900000 | E31: 87200000 | F31: 44900000
A32: Exchange Rate Adj | B32: 0 | C32: 0 | D32: 0 | E32: 0 | F32: 0
A33: Other Cash Adjustments | B33: 0 | C33: 0 | D33: 0 | E33: 0 | F33: 0
A34: Cash at End of Period | B34: 28760000 | C34: 22882000 | D34: 87200000 | E34: 44900000 | F34: 66400000

Sheet Income Statement 
A1: Data Sourced from : MorningStar
A2: Item | B2: 06/19 | C2: 06/20 | D2: 06/21 | E2: 06/22 | F2: 06/23
A3: Operating Revenue | B3: 1427167000 | C3: 1501079000 | D3: 2081600000 | E3: 3018300000 | F3: 3387200000
A4: Other Revenue | B4: 4808000 | C4: 5777000 | D4: 30500000 | E4: 9300000 | F4: 23800000
A5: ***Assumption Notes | D5: 15900000 | F5: 16200000
D6: 9030000
D7: =D4-D5-D6 -> 5570000 | F7: =F4-F5 -> 7600000 | G7: Other Revenue %
A8: YOY Avg Revenue | C8: =(C4-B4)/B4 -> 0.2015391 | D8: =(D7-C4)/C4 -> -0.035831747 | E8: =(E4-D7)/D7 -> 0.66965889 | F8: =(F7-E4)/E4 -> -0.1827957 | G8: =AVERAGE(C8:F8) -> 0.16314264
A9: Total Revenue Excluding Interest | B9: 1431975000 | C9: 1506856000 | D9: 2112100000 | E9: 3027600000 | F9: 3411000000
A10: Operating Expenses | B10: 1308638000 | C10: 1419032000 | D10: 1966300000 | E10: 2848800000 | F10: 3258300000 | G10: Operating expense %
A11: op exp to sales % | B11: =B10/B3 -> 0.91694805 | C11: =C10/C3 -> 0.94534132 | D11: =D10/D3 -> 0.94460992 | E11: =E10/E3 -> 0.94384256 | F11: =F10/F3 -> 0.96194497 | G11: =AVERAGE(B11:F11) -> 0.94253736
A12: EBITDA | B12: 123337000 | C12: 87824000 | D12: 145800000 | E12: 178800000 | F12: 152700000 | H12: 2019 | I12: 2020 | J12: 2021 | K12: 2022 | L12: 2023
A13: Depreciation | B13: -35246000 | C13: -37639000 | D13: -61800000 | E13: -92600000 | F13: -86400000 | G13: CAPEX | H13: 443331000 | I13: 454724000 | J13: 1011900000 | K13: 953900000 | L13: 848600000
A14: Amortisation | B14: -5127000 | C14: -7117000 | D14: -11000000 | E14: -11100000 | F14: -15500000 | G14: DEP/CAPEX | H14: =(B15/H13)*-1 -> 0.091067397 | I14: =(C15/I13)*-1 -> 0.098424539 | J14: =(D15/J13)*-1 -> 0.071943868 | K14: =(E15/K13)*-1 -> 0.10871161 | L14: =(F15/L13)*-1 -> 0.12008013
A15: Depreciation and Amortisation | B15: -40373000 | C15: -44756000 | D15: -72800000 | E15: -103700000 | F15: -101900000 | G15: AVERAGE | H15: =AVERAGE(H14:J14) -> 0.087145268
A16: EBIT(operating income) | B16: 82964000 | C16: 43068000 | D16: 73000000 | E16: 75100000 | F16: 50800000
A17: Interest Revenue | B17: 411000 | C17: 309000 | D17: 100000 | E17: 100000 | F17: 1000000
A18: Interest Expense | B18: -20363000 | C18: -11280000 | D18: -10400000 | E18: -12500000 | F18: -24100000 | G18: Interest Expense avg % | H18: 2024 | I18: 2025 | J18: 2026 | K18: 2027 | L18: 2028
B19: =B18*-1 -> 20363000 | C19: =C18*-1 -> 11280000 | D19: =D18*-1 -> 10400000 | E19: =E18*-1 -> 12500000 | F19: =F18*-1 -> 24100000 | G19: =AVERAGE(C20:F20) -> 0.15146369 | H19: =F19*(1+$G$19) -> 27750275 | I19: =H19*(1+$G$19) -> 31953434 | J19: =I19*(1+$G$19) -> 36793219 | K19: =J19*(1+$G$19) -> 42366056 | L19: =K19*(1+$G$19) -> 48782976
C20: =(C19-B19)/B19 -> -0.44605412 | D20: =(D19-C19)/C19 -> -0.078014184 | E20: =(E19-D19)/D19 -> 0.20192308 | F20: =(F19-E19)/E19 -> 0.928
A21: Net Interest Expense | B21: -19952000 | C21: -10971000 | D21: -10300000 | E21: -12400000 | F21: -23100000
A22: PreTax Profit | B22: 63012000 | C22: 32097000 | D22: 62700000 | E22: 62700000 | F22: 27700000
A23: Tax Expense | B23: -16336000 | C23: -9777000 | D23: -20500000 | E23: -17700000 | F23: 28100000
A24: Net Profit after Tax Before Abnormals | B24: 46676000 | C24: 22320000 | D24: 42200000 | E24: 45000000 | F24: 55800000
A25: Abnormals | B25: -44101000 | C25: -1052000 | D25: 34700000 | E25: -28900000 | F25: -284500000
A26: Abnormals Tax | B26: 9244000 | C26: 0 | D26: -4700000 | E26: 8100000 | F26: -1200000
A27: Net Abnormals | B27: -34857000 | C27: -1052000 | D27: 30000000 | E27: -20800000 | F27: -285700000
A28: Reported NPAT After Abnormals | B28: 11819000 | C28: 21268000 | D28: 72200000 | E28: 24200000 | F28: -229900000
A29: Outside Equity Interests | B29: 0 | C29: 0 | D29: 0 | E29: 0 | F29: 0
A30: Shares Outstanding at Period End | B30: 213734000 | C30: 214437000 | D30: 302627000 | E30: 303283000 | F30: 304248000
A31: Weighted Average Number of Shares | B31: 207222774 | C31: 214163264 | D31: 264273802 | E31: 303210210 | F31: 303851779
A32: EPS Adjusted (cents/share) | B32: 22.52 | C32: 10.42 | D32: 15.9 | E32: 14.84 | F32: 18.36
A33: EPS After Abnormals (cents/share) | B33: 5.7 | C33: 9.93 | D33: 27.2 | E33: 7.98 | F33: -75.66
A37: Notes**
A38: 1. The contraction termination fees was too high for 2021 of $15.9 million and there was legal settlement proceeds of $9.03 million which I have considered to be a one-off and have not considered to use it to value other revenue while taking an average.
A39: 2. The gain on sale and leaseback for year 2023 of $16.2million has been considered to be a one-off and I have not considered it to value it as an average to get future projections
A41: I did year on year avg to get other revenue

Sheet Balance Sheet 
A1: Data Sourced from : MorningStar
A2: Item | B2: 06/19 | C2: 06/20 | D2: 06/21 | E2: 06/22 | F2: 06/23 | J2: Working Capital 2022 | K2: Working Capital 2023
A3: CA - Cash | B3: 28760000 | C3: 22882000 | D3: 87200000 | E3: 44900000 | F3: 66400000 | J3: =E10-E26 -> 124300000 | K3: =F10-F26 -> 153600000
A4: CA - Receivables | B4: 161153000 | C4: 100117000 | D4: 348900000 | E4: 274700000 | F4: 306100000 | J4: Operating Revenue 2022 | K4: Operating Revenue 2023
A5: CA - Prepaid Expenses | B5: 18757000 | C5: 17302000 | D5: 12800000 | E5: 10800000 | F5: 11700000 | J5: ='Income Statement '!E3 -> 3018300000 | K5: ='Income Statement '!F3 -> 3387200000
A6: CA - Inventories | B6: 274146000 | C6: 257372000 | D6: 345000000 | E6: 317600000 | F6: 428700000 | J6: WC to Sales %
A7: CA - Investments | B7: 754000 | C7: 1309000 | D7: 1100000 | E7: 2700000 | F7: 200000 | J7: =J3/J5 -> 0.041182122 | K7: =K3/K5 -> 0.045347189
A8: CA - NCA Held Sale | B8: 0 | C8: 0 | D8: 0 | E8: 60500000 | F8: 1400000 | J8: Average NWC % | K8: =AVERAGE(J7:K7) -> 0.043264656
A9: CA - Other | B9: 6008000 | C9: 10703000 | D9: 38400000 | E9: 19100000 | F9: 17700000
A10: Total Current Assets | B10: 489578000 | C10: 409685000 | D10: 833400000 | E10: 730300000 | F10: 832200000
A11: NCA - Receivables | B11: 14028000 | C11: 2053000 | D11: 0 | E11: 0 | F11: 0
A12: NCA - Inventories | B12: 0 | C12: 0 | D12: 0 | E12: 0 | F12: 0 | P12: dep in fcf
A13: NCA - Investments | B13: 2057000 | C13: 2119000 | D13: 46600000 | E13: 47600000 | F13: 0 | G13: CAPEX % FOR FORECAST | J13: 2024 | K13: 2025 | L13: 2026 | N13: 2027 | O13: 2028
A14: NCA - PP&E | B14: 443331000 | C14: 454724000 | D14: 1011900000 | E14: 953900000 | F14: 848600000 | G14: =(E14-D14)/D14 -> -0.057317917 | H14: =(F14-E14)/E14 -> -0.11038893 | I14: CAPEX | J14: =F14*(1+$H$15) -> 7.7744199e+08 | K14: =J14*(1+$H$15) -> 7.1225081e+08 | L14: =K14*(1+$H$15) -> 6.5252614e+08 | M14: =L14*(1+$H$15) -> 5.9780959e+08 | N14: =L14*(1+$H$15) -> 5.9780959e+08 | O14: =N14*(1+$H$15) -> 5.4768121e+08 | P14: 1st step
A15: NCA - Intangibles(ExGW) | B15: 199614000 | C15: 201650000 | D15: 242100000 | E15: 240700000 | F15: 235000000 | G15: Average | H15: =AVERAGE(G14:H14) -> -0.083853423 | I15: DEPRECIATION | J15: =J14*'Income Statement '!$H$15 -> 67750390 | K15: =K14*'Income Statement '!$H$15 -> 62069288 | L15: =L14*'Income Statement '!$H$15 -> 56864566 | M15: =M14*'Income Statement '!$H$15 -> 52096277 | N15: =N14*'Income Statement '!$H$15 -> 52096277 | O15: =O14*'Income Statement '!$H$15 -> 47727826 | P15: 2nd step
A16: NCA - Goodwill | B16: 335533000 | C16: 346486000 | D16: 347400000 | E16: 347400000 | F16: 229500000
A17: NCA - Future Tax Benefit | B17: 4444000 | C17: 6696000 | D17: 4600000 | E17: 38900000 | F17: 7800000
A18: NCA - Other | B18: 0 | C18: 0 | D18: 100000 | E18: 0 | F18: 0
A19: Total NCA | B19: 999007000 | C19: 1013728000 | D19: 1652700000 | E19: 1628500000 | F19: 1320900000
A20: Total Assets | B20: 1488585000 | C20: 1423413000 | D20: 2486100000 | E20: 2358800000 | F20: 2153100000 | M20: Interest Expense
A21: CL - Account Payable | B21: 265866000 | C21: 253389000 | D21: 477400000 | E21: 449200000 | F21: 510000000 | M21: ='Income Statement '!F18*-1 -> 24100000
A22: CL - Short-Term Debt | B22: 13000 | C22: 2978000 | D22: 25500000 | E22: 21000000 | F22: 17200000
A23: CL - Provisions | B23: 49171000 | C23: 49607000 | D23: 139200000 | E23: 119300000 | F23: 134100000 | M23: Total debt
A24: CL - NCL Held Sale | B24: 0 | C24: 0 | D24: 0 | E24: 0 | F24: 0 | M24: =F22+F28 -> 467100000
A25: CL - Other | B25: 0 | C25: 0 | D25: 42800000 | E25: 16500000 | F25: 17300000
A26: Total Curr. Liabilities | B26: 315050000 | C26: 305974000 | D26: 684900000 | E26: 606000000 | F26: 678600000
A27: NCL - Account Payable | B27: 0 | C27: 0 | D27: 0 | E27: 0 | F27: 0 | M27: =F28/M24 -> 0.96317705
A28: NCL - Long-Term Debt | B28: 316058000 | C28: 255550000 | D28: 471000000 | E28: 401800000 | F28: 449900000 | M28: =AVERAGE(E28:F28) -> 425850000
A29: NCL - Provisions | B29: 31541000 | C29: 47850000 | D29: 69000000 | E29: 88600000 | F29: 16500000
A30: NCL - Other | B30: 0 | C30: 0 | D30: 500000 | E30: 0 | F30: 4400000
A31: Total NCL | B31: 347599000 | C31: 303400000 | D31: 540500000 | E31: 490400000 | F31: 470800000
A32: Total Liabilities | B32: 662649000 | C32: 609374000 | D32: 1225400000 | E32: 1096400000 | F32: 1149400000
A33: Share Capital | B33: 477494000 | C33: 480507000 | D33: 875700000 | E33: 878200000 | F33: 881000000
A34: Reserves | B34: 22860000 | C34: 20859000 | D34: 25900000 | E34: 26900000 | F34: 25700000
A35: Retained Earnings | B35: 325582000 | C35: 312673000 | D35: 359100000 | E35: 357300000 | F35: 97000000
A36: Other Equity | B36: 0 | C36: 0 | D36: 0 | E36: 0 | F36: 0
A37: Convertible Equity | B37: 0 | C37: 0 | D37: 0 | E37: 0 | F37: 0
A38: SE Held Sale | B38: 0 | C38: 0 | D38: 0 | E38: 0 | F38: 0
A39: Outside Equity | B39: -- | C39: -- | D39: -- | E39: -- | F39: --
A40: Total Equity | B40: 825936000 | C40: 814039000 | D40: 1260700000 | E40: 1262400000 | F40: 1003700000

Sheet Beta
A1: Source: https://finbox.com/ASX:BGA/models/wacc/
A2: Comparable Companies | B2: Levered Beta | C2: Debt / Capital | D2: Marginal Tax Rate | E2: Unlevered Beta | F2: Adjusted Unlevered Beta
A3: Inghams Group Limited | B3: 0.41 | C3: 0.579 | D3: 0.26 | E3: 0.2 | F3: 0.47
A4: Ricegrowers Limited | B4: 0.56 | C4: 0.386 | D4: 0.21 | E4: 0.37 | F4: 0.58
A5: Ridley Corporation Limited | B5: 0.47 | C5: 0.12 | D5: 0.29 | E5: 0.43 | F5: 0.62
A6: FFI Holdings Limited | B6: 0.15 | C6: 0 | D6: 0.24 | E6: 0.15 | F6: 0.44
A7: Cobram Estate Olives Limited | B7: 0.6 | C7: 0.229 | D7: 0.36 | E7: 0.51 | F7: 0.67
A8: ASX:BGA | B8: 0.52 | C8: 0.28 | D8: 0.28 | E8: 0.41 | F8: 0.6
A10: Average | B10: 0.45 | C10: 0.266 | D10: 0.273 | E10: 0.34 | F10: 0.56
B12: Low | C12: High
A13: Selected Unlevered Beta | B13: 0.55 | C13: 0.65
A14: Debt % of Capital (Adj According to Annual Report) | B14: 0.2 | C14: 0.4 | E14: Beta Values | F14: Source
A15: Equity % of Capital | B15: 0.8 | C15: 0.6 | E15: 0.76 | F15: mornignstar
A16: Tax Rate (Adj According to Annual Report) | B16: 0.3 | C16: 0.3 | E16: 0.81 | F16: https://www.barrons.com/market-data/stocks/bga?countrycode=au
E17: 0.82 | F17: https://finbox.com/ASX:BGA/models/wacc/
A18: Re-levered Beta | B18: =ROUND(B13*(1+(1-B16)*(B14/B15)),2) -> 0.65 | C18: =ROUND(C13*(1+(1-C16)*(C14/C15)),2) -> 0.95 | E18: 0.8 | F18: I calculated
A19: Average | B19: =(B18+C18)/2 -> 0.8 | E19: =AVERAGE(E15:E18) -> 0.7975
